Workbook
Name a: #REF!
Name AUGUST: #REF!
Name CAPSTOCK: #REF!
Name CASHREC: #REF!
Name check1: #REF!
Name CHECKLIST: #REF!
Name cklst: [3]Chklst!$A$1:$C$26
Name CLASSEXP: #REF!
Name COST: #REF!
Name COST2: #REF!
Name Days: '[4]Cost Rollforward - PTO'!$C$45
Name Days_2: '[5]Cost Roll'!$C$52
Name DERIVATIVE: #REF!
Name DETAIL: #REF!
Name DISTREC: #REF!
Name DISTRIBUTION: #REF!
Name DVD: #REF!
Name DVDII: #REF!
Name EntityNames: [6]EntityLookup!$A$3:$A$5
Name EXPENSES: #REF!
Name Facility_Name: '[7]PAR Settled'!$B:$B
Name fadfs: '[8]Cost Roll'!$C$24
Name FAX: #REF!
Name foursixtythree: #REF!
Name GAIN: #REF!
Name Gain_Loss_01: #REF!
Name Gain_Loss_02: #REF!
Name Gain_Loss_03: #REF!
Name Gain_Loss_04: #REF!
Name Gain_Loss_05: #REF!
Name Gain_Loss_06: #REF!
Name Gain_Loss_07: #REF!
Name Gain_Loss_08: #REF!
Name Gain_Loss_09: #REF!
Name Gain_Loss_10: #REF!
Name Gain_Loss_11: #REF!
Name Gain_Loss_12: #REF!
Name GAINLOSS: #REF!
Name INT: #REF!
Name INTEREST: #REF!
Name INTEREST2: #REF!
Name IO_14: '[9]501773CG8sold'!$A$59:$L$80
Name IO_15: '[9]23322BFC7soldoff'!$A$45:$L$67
Name IO_16: '[9]3133TKAB6Sold Off'!$A$42:$L$63
Name IO_17: '[9]3133TGQG7 paid off'!$A$40:$L$61
Name IO_18: '[9]3133TKT91Sold Off'!$A$40:$L$61
Name IO_19: '[9]3133t2wf3- paid off'!$A$37:$L$58
Name IO_20: '[9]3133TKYZ7PaidOff'!$A$39:$L$60
Name IO_6: '[9]312915gc9paidoff'!$A$298:$T$320
Name Issuer_Name: '[7]PAR Settled'!$A:$A
Name JULY: #REF!
Name JUNE: #REF!
Name LOAN: #REF!
Name Marketing_Explanation: '[6]Sponsor Due Dillig Explan'!$A$3:$A$110
Name MgmtDealLIst: '[6]Deal_Expense Lookup'!$A$1:$A$106
Name MISCADJ: #REF!
Name MISCADJ2: #REF!
Name MKTVALUE: #REF!
Name MKTVALUE2: #REF!
Name MMINT: #REF!

Sheet Borrowing Base
A1: SAMPLE FLOATING RATE FUNDING I, LLC
A2: BORROWING BASE CERTIFICATE
A3: Amounts are pro forma for proposed borrowing and related use of proceeds
A4: DETERMINATION DATE | J4: 45869
A5: CONCENTRATION TEST AMOUNT | J5: ='Loan List'!DH6 | O5: Cash and Credit Facility Balance Projections
A8: BORROWING BASE - (A) minus (B) minus (A)(iv) | J8: =J10-J18-J14 | K8: ='Loan List'!GA6-J14 | O8: AUD
K9: Check | O9: 0 | P9: Current Credit Facility Balance
B10: (A) | C10: Aggregate Collateral Balance (without duplication) sum of (i)-(vi) | J10: =SUM(J11:J16) | K10: =J10='Loan List'!DG6 | O10: =+O71 | P10: Borrowing
C11: (i) Aggregate Principal Balance of all Collateral Loans (other than Defaulted, Restructured, Haircut Ineligible, and Discount) | J11: ='Loan List'!HV8 | O11: =SUM(O9:O10) | P11: Projected Credit Facility Balance
C12: (ii) Defaulted Collateral Loan Balance | J12: ='Loan List'!IA8 | O12: USD
C13: (iii) The aggregate purchase price of all Discount Loans that are Eligible Collateral Loans and not Defaulted, Haircut or Restructured | J13: ='Loan List'!HZ8 | O13: =325500000-20800000+23000000+3000000-12000000+1200000+6000000+9500000+7500000-3000000-17000000+5000000+15000000+4000000+35500000-13000000+19000000+5000000+6000000+3500000-27000000+18000000+10000000+5000000+5000000-10000000+17000000+19000000+13000000-200000000-6000000+4000000+4000000-10000000+8000000+18000000+10000000+16000000+5000000+21000000+27000000+40000000+5000000+15000000+16000000-27000000+15000000+8000000+15000000+18000000-54000000+20000000-58000000-23000000-43000000-15000000-46000000+10000000+10000000+7500000-6500000-115000000+32000000+46000000-81000000+8000000+50000000+12000000+69000000+11000000-80000000-50000000-25500000+11000000+20000000+10000000+10000000+20000000+20000000-5000000-65000000+20000000+60000000+30000000+20000000-35000000-7000000+10000000-40000000-50000000+30000000-48000000+20000000-45000000-35000000+15000000-35000000-55000000+15000000+160000000+75000000+50000000+30000000-130000000-42000000+50000000+55000000+40000000+50000000+80000000+20000000+100000000+20000000+25000000+50000000-320000000-30000000+20000000-55000000+25000000+20000000+75000000 | P13: Current Credit Facility Balance
C14: (iv) The aggregate Unfunded Commitments of all Delayed Drawdown and Revolvers that are Eligible Loans | J14: ='Loan List'!HU8 | O14: =+O33 | P14: Borrowing
C15: (v) The Credit Improved Loan Balance | J15: ='Loan List'!HY8 | O15: =SUM(O13:O14) | P15: Projected Credit Facility Balance
C16: (vi) The Haircut Collateral Loan Balance | J16: ='Loan List'!HX8 | O16: CAD
O17: 2000000 | P17: Current Credit Facility Balance
B18: (B) | C18: Excess Concentration Amount | J18: =SUM('Loan List'!HG10:HG117) | O18: 0 | P18: Borrowing
O19: =SUM(O17:O18) | P19: Projected Credit Facility Balance
A20: MAXIMUM AVAILABLE AMOUNT - Least of (A), (B) and (C) | J20: =MIN(J27,J35,J40) | O20: EUR
O21: 0 | P21: Current Credit Facility Balance
C22: Least of: | O22: 0 | P22: Borrowing
O23: =SUM(O21:O22) | P23: Projected Credit Facility Balance
B24: (A) | D24: Facility Amount, less | J24: 718000000
D25: Revolving Exposure, plus | J25: ='Loan List'!$DF$6 | O25: 393842760
D26: Amount on deposit in the Revolving Reserve Account | J26: 0 | O26: =+J46-O25 | P26: Check
J27: =J24-J25+J26
O28: =+J53 | P28: Equity/Cushion
B29: (B) | C29: (i) | D29: (x) Borrowing Base, multipled by | J29: ='Borrowing Base'!J8 | O29: =+J18 | P29: Net Penalty
D30: (y) Weighted Average Advance Rate, minus | J30: ='Loan List'!AZ2
C31: (ii) | D31: Foreign Currency Variability Reserve, minus | J31: ='Loan List'!DL6 | O31: USD
C32: (iii) | D32: Revolving Exposure, plus | J32: ='Loan List'!$DF$6 | O32: 36200325 | P32: Cash - Current & PreBorrowing
C33: (iv) | D33: Cash on deposit in Principal Collection Subaccount | J33: 36362717
C34: (v) | D34: Amount on deposit in the Revolving Reserve Account | J34: =J26 | O34: =SUM(O32:O33) | P34: Cash - Budgeted & PostBorrowing
J35: =(J29*J30)-J31-J32+J33+J34
B37: (C) | C37: (A) | D37: Aggregate Collateral Balance, minus | J37: =J10-J14
C38: (B) | D38: Minimum Equity Amount, plus | J38: 1.1655229e+08
C39: (C) | D39: Cash on deposit in Principal Collection Subaccount | J39: =J33
J40: =J37-J38+J39
A42: ADVANCES OUTSTANDING
A44: Advances Outstanding at beginning of the Interest Accrual Period | J44: 393842760
A45: Advances/(Repayments) during the period through and including 07/31/2025 | J45: 0
...

Sheet Loan List
B1: ='Borrowing Base'!A1 | AG1: 20% Conc. Limit | AJ1: Level 1 - 10% Haircut | AM1: Level 2 - 20% Haircut | AP1: Level 3 - 35% Haircut | AS1: Level 4 - Max Eligibility - 50% Haircut | GH1: No of Industry | GI1: Limit | GJ1: Limit $ | GQ1: No of Obligor | GR1: Limit % | GS1: Limit $ | GZ1: No of Obligor | HA1: Limit % | HB1: Limit $ | HC1: Total Excess
B2: Loan List | AG2: Tier 1 Obligor | AH2: Tier 2 Obligor | AI2: Tier 3 Obligor | AJ2: Tier 1 Obligor | AK2: Tier 2 Obligor | AL2: Tier 3 Obligor | AM2: Tier 1 Obligor | AN2: Tier 2 Obligor | AO2: Tier 3 Obligor | AP2: Tier 1 Obligor | AQ2: Tier 2 Obligor | AR2: Tier 3 Obligor | AS2: Tier 1 Obligor | AT2: Tier 2 Obligor | AU2: Tier 3 Obligor | AY2: Weighted Average Advance Rate: | AZ2: =SUMPRODUCT(($GB10:$GB406>0)*$GB10:$GB406*$V10:$V406)/SUMPRODUCT(($GB10:$GB406>0)*$GB10:$GB406) | DM2: Limit % | DN2: 0.15 | DQ2: 0.1 | DT2: 0.05 | DW2: 0.15 | DZ2: 0.1 | EC2: 0.15 | EF2: 0.1 | EI2: 0.25 | EL2: 0.1 | EO2: 0.03 | ER2: 0.15 | EU2: 0.05 | EX2: 0.15 | FA2: 0.1 | FD2: 0.15 | FP2: 0.05 | FS2: 0.2 | FV2: 0.2 | GH2: 1 | GI2: 0.25 | GJ2: ='Borrowing Base'!J5*GI2 | GQ2: 3 | GR2: 0.06666666 | GS2: ='Borrowing Base'!J5*GR2 | GZ2: 5 | HA2: 0.3 | HB2: =HA2*'Borrowing Base'!J5 | HC2: =MAX(0,SUM(HA10:HA11)-HB2)
B3: Loan Portfolio as of: July 31, 2025 | AF3: SD/EBITDA | AG3: 5 | AH3: 4.25 | AI3: 3.75 | AJ3: 5.5 | AK3: 4.75 | AL3: 4.25 | AM3: 6 | AN3: 5.25 | AO3: 4.75 | AP3: 6.5 | AQ3: 5.75 | AR3: 5.25 | AS3: 7 | AT3: 6.25 | AU3: 5.75 | AY3: Weighted Average Coupon: | AZ3: =IFERROR(SUMPRODUCT((AS10:AS406>0)*DG10:DG406*AS10:AS406)/SUMPRODUCT((AS10:AS406>0)*DG10:DG406),"N/A") | DM3: Limit | DN3: =DN2*'Borrowing Base'!$J$5 | DQ3: =DQ2*'Borrowing Base'!$J$5 | DT3: =DT2*'Borrowing Base'!$J$5 | DW3: =DW2*'Borrowing Base'!$J$5 | DZ3: =DZ2*'Borrowing Base'!$J$5 | EC3: =EC2*'Borrowing Base'!$J$5 | EF3: =EF2*'Borrowing Base'!$J$5 | EI3: =EI2*'Borrowing Base'!$J$5 | EL3: =EL2*'Borrowing Base'!$J$5 | EO3: =EO2*'Borrowing Base'!$J$5 | ER3: =ER2*'Borrowing Base'!$J$5 | EU3: =EU2*'Borrowing Base'!$J$5 | EX3: =EX2*'Borrowing Base'!$J$5 | FA3: =FA2*'Borrowing Base'!$J$5 | FD3: =FD2*'Borrowing Base'!$J$5 | FP3: =FP2*'Borrowing Base'!$J$5 | FS3: =FS2*'Borrowing Base'!$J$5 | FV3: =FV2*'Borrowing Base'!$J$5 | GH3: 2 and 3 | GI3: 0.15 | GJ3: ='Borrowing Base'!J5*GI3 | GQ3: 5 | GR3: 0.06 | GS3: ='Borrowing Base'!J5*GR3
AF4: TD/EBITDA | AG4: 7 | AH4: 6 | AI4: 5 | AJ4: 7.5 | AK4: 6.5 | AL4: 5.5 | AM4: 8 | AN4: 7 | AO4: 6 | AP4: 8.5 | AQ4: 7.5 | AR4: 6.5 | AS4: 9 | AT4: 8 | AU4: 7 | AY4: Specified Term SOFR: | AZ4: 0.0432224 | DM4: Total | DN4: =SUM(DN10:DN406) | DQ4: =SUM(DQ10:DQ406) | DT4: =SUM(DT10:DT406) | DW4: =SUM(DW10:DW406) | DZ4: =SUM(DZ10:DZ406) | EC4: =SUM(EC10:EC406) | EF4: =SUM(EF10:EF406) | EI4: =SUM(EI10:EI406) | EL4: =SUM(EL10:EL406) | EO4: =SUM(EO10:EO406) | ER4: =SUM(ER10:ER406) | EU4: =SUM(EU10:EU406) | EX4: =SUM(EX10:EX406) | FA4: =SUM(FA10:FA406) | FD4: =SUM(FD10:FD406) | FP4: =SUM(FP10:FP406) | FS4: =SUM(FS10:FS406) | FV4: =SUM(FY10:FY406) | FW4: =SUM(FW10:FW406) | FX4: =SUM(FX10:FX406) | FY4: =SUM(FY10:FY406) | GH4: Other | GI4: 0.15 | GJ4: ='Borrowing Base'!J5*GI4 | GQ4: All others | GR4: 0.05 | GS4: ='Borrowing Base'!J5*GR4
AF5: UD/EBITDA | AG5: 6 | AH5: 5.25 | AI5: 4.5 | AJ5: 6.5 | AK5: 5.75 | AL5: 5 | AM5: 7 | AN5: 6.25 | AO5: 5.5 | AP5: 7.5 | AQ5: 6.75 | AR5: 6 | AS5: 8 | AT5: 7.25 | AU5: 6.5 | AV5: Weighted Average Life: | AW5: =SUMPRODUCT(AQ10:AQ406,$DG$10:$DG$406)/SUM($DG$10:$DG$406) | AY5: Weighted Average Spread: | AZ5: =SUM($CB$10:$CC$406)/SUMIF($AR$10:$AR$406,"No",$DE$10:$DE$406) | CX5: =SUM(CX10:CX406) | CY5: =SUM(CY10:CY406) | CZ5: =SUM(CZ10:CZ406) | DA5: =SUM(DA10:DA406) | DB5: =SUM(DB10:DB406) | DC5: =SUM(DC10:DC406) | DM5: Excess | DN5: =MAX(0,DN4-DN3) | DQ5: =MAX(0,DQ4-DQ3) | DT5: =MAX(0,DT4-DT3) | DW5: =MAX(0,DW4-DW3) | DZ5: =MAX(0,DZ4-DZ3) | EC5: =MAX(0,EC4-EC3) | EF5: =MAX(0,EF4-EF3) | EI5: =MAX(0,EI4-EI3) | EL5: =MAX(0,EL4-EL3) | EO5: =MAX(0,EO4-EO3) | ER5: =MAX(0,ER4-ER3) | EU5: =MAX(0,EU4-EU3) | EX5: =MAX(0,EX4-EX3) | FA5: =MAX(0,FA4-FA3) | FD5: =MAX(0,FD4-FD3) | FP5: =MAX(0,FP4-FP3) | FQ5: Haircut Excess | FS5: =MAX(0,FS4-FS3) | FT5: Haircut Excess | FV5: =MAX(0,SUM(FY4:FY4)-FV3) | FZ5: Haircut Excess | GG5: =COUNTIF(GF10:GF406,">"&0) | GP5: =COUNTIF(GP10:GP406,">"&0) | GY5: =COUNTIF(GY10:GY406,">"&0)
DE6: =SUM(DE10:DE406) | DF6: =SUM(DF10:DF406) | DG6: =SUM(DG10:DG406) | DH6: =SUM(DH10:DH406) | DI6: =SUM(DI10:DI406) | DL6: =SUM(DL10:DL406) | DM6: Haircut | DN6: =IF(DN4<0.01,0,DN5/DN4) | DO6: =SUM(DO10:DO406) | DP6: =SUM(DP10:DP406) | DQ6: =IF(DQ4<0.01,0,DQ5/DQ4) | DR6: =SUM(DR10:DR406) | DS6: =SUM(DS10:DS406) | DT6: =IF(DT4<0.01,0,DT5/DT4) | DU6: =SUM(DU10:DU117) | DV6: =SUM(DV10:DV117) | DW6: =IF(DW4<0.01,0,DW5/DW4) | DX6: =SUM(DX10:DX406) | DY6: =SUM(DY10:DY406) | DZ6: =IF(DZ4<0.01,0,DZ5/DZ4) | EA6: =SUM(EA10:EA406) | EB6: =SUM(EB10:EB406) | EC6: =IF(EC4<0.01,0,EC5/EC4) | ED6: =SUM(ED10:ED406) | EE6: =SUM(EE10:EE406) | EF6: =IF(EF4<0.01,0,EF5/EF4) | EG6: =SUM(EG10:EG406) | EH6: =SUM(EH10:EH406) | EI6: =IF(EI4<0.01,0,EI5/EI4) | EJ6: =SUM(EJ10:EJ406) | EK6: =SUM(EK10:EK406) | EL6: =IF(EL4<0.01,0,EL5/EL4) | EM6: =SUM(EM10:EM406) | EN6: =SUM(EN10:EN406) | EO6: =IF(EO4<0.01,0,EO5/EO4) | EP6: =SUM(EP10:EP406) | EQ6: =SUM(EQ10:EQ406) | ER6: =IF(ER4<0.01,0,ER5/ER4) | ES6: =SUM(ES10:ES406) | ET6: =SUM(ET10:ET406) | EU6: =IF(EU4<0.01,0,EU5/EU4) | EV6: =SUM(EV10:EV406) | EW6: =SUM(EW10:EW406) | EX6: =IF(EX4<0.01,0,EX5/EX4) | EY6: =SUM(EY10:EY406) | EZ6: =SUM(EZ10:EZ406) | FA6: =IF(FA4<0.01,0,FA5/FA4) | FB6: =SUM(FB10:FB406) | FC6: =SUM(FC10:FC406) | FD6: =IF(FD4<0.01,0,FD5/FD4) | FE6: =SUM(FE10:FE406) | FF6: =SUM(FF10:FF406) | FH6: =SUM(FH10:FH406) | FI6: =SUM(FI10:FI406) | FJ6: =SUM(FJ10:FJ406) | FK6: =SUM(FK10:FK406) | FL6: =SUM(FL10:FL406) | FN6: =SUM(FN10:FN406) | FO6: =SUM(FO10:FO406) | FP6: =IF(FP4<0.01,0,FP5/FP4) | FQ6: =SUM(FQ10:FQ406) | FR6: =SUM(FR10:FR406) | FS6: =IF(FS4<0.01,0,FS5/FS4) | FT6: =SUM(FT10:FT406) | FU6: =SUM(FU10:FU406) | FV6: =IF(SUM(FV4:FY4)<0.01,0,FV5/SUM(FY4:FY4)) | FZ6: =SUM(FZ10:FZ406) | GA6: =SUM(GA10:GA406) | GB6: =SUM(GB10:GB406) | GC6: =SUM(GC10:GC406) | GG6: =SUM(GG10:GG406) | GH6: =GG5 | GI6: =SUM(GI10:GI406) | GK6: =SUM(GK10:GK406) | GP6: =SUM(GP10:GP406) | GQ6: =GP5 | GR6: =SUM(GR10:GR406) | GT6: =SUM(GT10:GT406) | GY6: =SUM(GY10:GY406) | GZ6: =GY5 | HA6: =SUM(HA10:HA406) | HC6: =SUM(HC10:HC406) | HG6: =SUM(HG10:HG406) | HH6: =SUM(HH10:HH117) | HU6: Eligible Unfunded
G7: =SUM(G10:G406) | H7: =SUM(H10:H406) | J7: =SUM(J10:J406) | K7: =SUM(K10:K406) | L7: =SUM(L10:L406) | M7: =SUM(M10:M406) | O7: =SUMIF(N10:N406,"Yes",K10:K406) | W7: =SUM(W10:W406) | HS7: =SUM(HS10:HS406)
L8: Eligible Balances | N8: Loan Value Criteria | AA8: Credit/Performance Metrics | AR8: Interest Metrics | BE8: Other Loan Characteristics | BN8: Eligibility Criteria | CE8: Eligibility Criteria | DN8: Excess Concentrations | HN8: =SUM(HN10:HN406) | HO8: =SUM(HO10:HO406) | HU8: =SUMIF($HT$10:$HT$117,"",$HU$10:$HU$117) | HV8: =SUMIF(HV10:HV406,"> 0",HO10:HO406) | HW8: =SUM(HW10:HW406) | HX8: =SUM(HX10:HX406) | HY8: =SUM(HY10:HY406) | HZ8: =SUM(HZ10:HZ406) | IA8: =SUM(IA10:IA406)
B9: Loan Number | C9: Obligor | D9: Obligor Name | E9: Security Name | F9: Purchase Date (Date Loan contributed to the facility) | G9: Total Commitment (Issue Currency) | H9: Outstanding Principal Balance (Issue Currency) | I9: Exchange Rate | J9: Total Commitment (USD) | K9: Outstanding Principal Balance (USD) | L9: Eligible Commitment (USD) | M9: Eligible Outstanding Principal Balance (USD) | N9: Defaulted Collateral Loan / Material Mod (Y/N) | O9: Date of Default | P9: Months Since Default | Q9: Credit Improved Loan (Y/N) | R9: Purchase Price | S9: Discount Collateral Loan (Y/N) | T9: Market Value | U9: Applicable Recovery Rate | V9: Advance Rate | W9: Aggregate Collateral Balance (Pre-Eligibility; Excluding Unfunded; Excluding Principal Acct) | X9: Stretch Senior Loan (Y/N) | Y9: Lien Type (First Lien / Split First Lien / Split Lien / Second Lien) | Z9: Loan Type (Term / Delayed Draw / Revolver) | AA9: Current Moody's Rating | AB9: Current S&P Rating | AC9: Initial Fixed Charge Coverage Ratio | AD9: Current Fixed Charge Coverage Ratio | AE9: Current Interest Coverage Ratio | AF9: Initial Debt to Capitalization Ratio | AG9: Initial Senior Debt/ EBITDA | AH9: Initial Total Debt/ EBITDA | AI9: Current Senior Debt/ EBITDA | AJ9: Current Total Debt/ EBITDA | AK9: Initial TTM EBITDA | AL9: Current TTM EBITDA | AM9: Current As of Date For Leverage and EBITDA | AN9: Tier 1 / Tier 2 Obligor | AO9: Maturity Date | AP9: Rem. Term to Maturity | AQ9: Avg Life | AR9: Fixed Rate (Y/N) | AS9: Coupon incl. PIK and PIK'able (if Fixed) | AT9: Floor Obligation (Y/N) | AU9: Floor | AV9: Spread incl. PIK and PIK'able | AW9: Base Rate | AX9: Greater of Base Rate and Floor | AY9: For Revolvers/Delayed Draw, commitment or other unused fee | AZ9: PIK / PIK'able For Floating Rate Loans | BA9: PIK / PIK'able For Fixed Rate Loans | BB9: Cash Spread On Floating Rate Loans | BC9: Cash Spread On Fixed Rate Loans | BD9: Interest Paid | BE9: Obligor Industry | BF9: Currency (USD / CAD / GBP / AUD / EUR) | BG9: Obligor Country | BH9: DIP Loan (Y/N) | BI9: Partial PIK Loan (Y/N) | BJ9: Non-Cash PIK Loan (Y/N) | BK9: Warrants to Purchase Equity (Y/N) | BL9: LBO Loan (Y/N) | BM9: Parti-cipation (Y/N) | BN9: Convertible to Equity (Y/N) | BO9: Equity Security (Y/N) | BP9: At Acquisition - Subject to offer or called for redemption (Y/N) | BQ9: Margin Stock (Y/N) | BR9: Subject to withholding tax (Y/N) | BS9: At Acquisition - Defaulted Collateral Loan | BT9: Zero Coupon Obligation(Y/N) | BU9: Covenant Lite (Y/N) | BV9: Eligible Covenant Lite (Y/N) | BW9: Structured Finance Obligation, finance lease or chattel paper (Y/N) | BX9: Material Non-Credit Related Risk (Y/N) | BY9: Primarily Secured by Real Estate, Construction Loan or Project Finance Loan (Y/N) | BZ9: Interest Only Security (Y/N) | CA9: Satisfies all Other Eligibility Criteria (Y/N) | CB9: Aggregate Funded Spread | CC9: Aggregate Unfunded Spread | CE9: Purchased Below 85% of Par | CF9: Eligible Currency | CG9: Eligible Country | CH9: Convertible to Equity | CI9: Equity Security | CJ9: Subject to offer or called for redemption | CK9: Margin Stock | CL9: Subject to withholding tax | CM9: At Acquisition - Defaulted Collateral Loan | CN9: Non-cash PIK | CO9: Zero Coupon Obligation | CP9: Covenant Lite | CQ9: Structured Finance Obligation | CR9: Remaining term > 7 yrs | CS9: Interest Paid At Least Semi Annually | CT9: Material Non-Credit Related Risk | CU9: Real Estate, Construction or Project Finance Loan | CV9: Interest Only Security | CW9: Satisfies all Other Eligibility Criteria | CX9: EBITDA Requirement at Acquisition | CY9: EBITDA Requirement Ongoing | CZ9: Leverage 10% Haircut | DA9: Leverage 20% Haircut | DB9: Leverage 35% Haircut | DC9: Leverage - Final Haircut - 50% | DD9: Total Ineligible (excl. EBITDA and Leverage Ongoing) | DE9: Aggregate Collateral Balance (Post Eligibility; Including Haircut Ineligible; Excluding Unfunded) | DF9: Eligible Unfunded | DG9: Aggregate Collateral Balance (Post Eligibility; Including Eligible Unfunded) | DH9: Concentration Test Balance - OPB + Eligible Unfunded | DI9: Revolving Exposure | DJ9: Foreign Currency Loan OC Balance | DK9: Foreign Currency Variability Factor | DL9: Foreign Currency Variability Reserve | DN9: Second Lien and Split Lien | DO9: Excess | DP9: Net Loan Balance | DQ9: Second Lien | DR9: Excess | DS9: Net Loan Balance | DT9: DIP Collateral Loans | DU9: Excess | DV9: Net Loan Balance | DW9: Eligible Foreign Country | DX9: Excess | DY9: Net Loan Balance | DZ9: Partial PIK Loan | EA9: Excess | EB9: Net Loan Balance | EC9: Revolving / Delayed Drawdown | ED9: Excess | EE9: Net Loan Balance | EF9: Discount Loans | EG9: Excess | EH9: Net Loan Balance | EI9: Credit Improved Loans | EJ9: Excess | EK9: Net Loan Balance | EL9: Less than Quarterly Pay | EM9: Excess | EN9: Net Loan Balance | EO9: Warrants to Purchase Equity Securities | EP9: Excess | EQ9: Net Loan Balance | ER9: LBO Loan with Equity to Cap <25% | ES9: Excess | ET9: Net Loan Balance | EU9: Participation Interests | EV9: Excess | EW9: Net Loan Balance | EX9: Eligible Covenant Lite Loans | EY9: Excess | EZ9: Net Loan Balance | FA9: Fixed Rate Loan | FB9: Excess | FC9: Net Loan Balance | FD9: Agreed Foreign Currency | FE9: Excess | FF9: Net Loan Balance | FG9: Obligor | FH9: Excess | FI9: Net Loan Balance | FJ9: Obligor Industry | FK9: Excess | FL9: Net Loan Balance | FM9: Top 5 Obligors | FN9: Excess | FO9: Net Loan Balance | FP9: LTM EBITDA >= 5,000,000 but < 7,500,000 | FQ9: Excess; Haircut to 1-Recovery Rate | FR9: Net Loan Balance | FS9: LTM EBITDA < 15,000,000 | FT9: Excess; Haircut to 1-Recovery Rate | FU9: Net Loan Balance | FV9: LTM Snr Debt / EBITDA | FW9: LTM Total Debt / EBITDA | FX9: Stretch Senior LTM Total Debt / EBITDA | FY9: Exceeds Leverage Limitation | FZ9: Excess; Haircut to 1-Min(90% and Market Value) | GA9: Excess Concentration Test | GB9: Net Loan Balance | GC9: Borrowing Base | GE9: Industry No | GF9: Lookups'!F2:F3 Loan Balance | GG9: Industry Loan Balance | GH9: Industry Order | GI9: Outstanding Loan Balance | GJ9: Limit | GK9: Excess | GL9: Industry No (Matched) | GM9: Haircut | GO9: Obligor No | GP9: Obligor Loan Balance | GQ9: Obligor Order | GR9: Obligor Loan Balance | GS9: Limit | GT9: Excess | GU9: Obligor No | GV9: Haircut | GX9: Obligor No | GY9: Obligor Loan Balance | GZ9: Obligor Order | HA9: Obligor Loan Balance | HB9: Limit | HC9: Excess | HD9: Obligor No | HE9: Haircut | HG9: Excess Concentration Amount (Dynamic) | HH9: Excess Concentration Amount (HARD CODE on Last Day of Reinvestment Period) | HI9: Applicable Excess Concentration Amount (Last Day of Reinvestment Period) | HK9: Obligor No | HL9: Obligor Loan Balance | HN9: Aggregate Collateral Balance (Pre-Eligibility; Excluding Unfunded; Excluding Principal Acct) | HO9: Outstanding Principal Balance | HP9: Defaulted Collateral Loan Balance | HQ9: Discount Loan Balance | HR9: Credit Improved Balance | HS9: Haircut Ineligible | HT9: Ineligibles | HU9: Total Unfunded | HV9: APB (Other Than Def, Inelib, Restructured, Haircut) | HW9: Ineligibles Test | HX9: Haircut Test | HY9: Credit Improved Test | HZ9: Discount Test | IA9: Defaulted Test | IB9: Lookups'!F2:F3 No | IE9: Initial Haircut Level
A10: =D10 | B10: 1 | C10: 1 | D10: Northgate Holdings, LLC | E10: Northgate (TL) | G10: 18406747 | H10: 18406747 | I10: 1 | J10: =IF(B10="","",G10*I10) | K10: =IF(B10="","",H10*I10) | L10: =IF(B10="","",IF(COUNTIF($CE10:$CX10,1)>0,0,J10)) | M10: =IF(B10="","",IF(COUNTIF($CE10:$CX10,1)>0,0,K10)) | N10: No | O10: N/A | P10: =IF(B10="","",IF(OR(O10="N/A",O10=""),0,YEARFRAC('Borrowing Base'!$J$4,'Loan List'!O10)*12)) | Q10: No | R10: 0.9975 | S10: =IF(B10="","",IF(R10<95%,"Yes","No")) | T10: 0.99 | U10: =IF(B10="","",IF(OR(Y10="First Lien",Y10="Split First Lien",Y10="Tier 1 Split Lien",Y10="Tier 2 Split Lien"),50%,30%)) | V10: =IF(B10="",0,IF(AND(Y10="First Lien",AN10="Tier 1"),IF(AND(X10="Yes",MIN(AH10,$AJ$5)>4.5),(((4.5/MIN(AH10,$AJ$5))*72.5%)+(((MIN(AH10,$AJ$5)-4.5)/MIN(AH10,$AJ$5))*35%)),72.5%),IF(AND(Y10="First Lien",AN10="Tier 2"),IF(AND(X10="Yes",MIN(AH10,$AK$5)>4.5),(((4.5/MIN(AH10,$AK$5))*72.5%)+(((MIN(AH10,$AK$5)-4.5)/MIN(AH10,$AK$5))*35%)),72.5%),IF(AND(X10="Yes",MIN(AH10,$AL$5)>4),(((4/MIN(AH10,$AL$5))*72.5%)+(((MIN(AH10,$AL$5)-4)/MIN(AH10,$AL$5))*35%)),IF(OR(Y10="First Lien",Y10="Split First Lien"),72.5%,IF(Y10="Split Lien", 53%,35%)))))) | W10: =IF($C10="","",MIN($HO10:$HS10)) | X10: Yes | Y10: First Lien | Z10: Term | AA10: NR | AB10: NR | AC10: 1.1174448 | AD10: 5.1870295 | AE10: 4.6060902 | AF10: 0.4590766 | AG10: 5.1870295 | AH10: 5.1870295 | AI10: 4.6060902 | AJ10: 4.6060902 | AK10: 33738000 | AL10: 77650021 | AM10: 45747 | AN10: =IF(C10="","",(IF(AK10>=50000000,"Tier 1",(IF(OR(AK10>=20000000,AND(AK10>5000000,AC10>=1.25,AF10<=0.65)),"Tier 2","Tier 3"))))) | AO10: 47393 | AP10: 4.1722222 | AQ10: =IF(C10="","",AP10) | AR10: No | AS10: 0 | AT10: Yes | AU10: 0.01 | AV10: 0.0475 | AW10: 0.042906 | AX10: =IF(C10="","",MAX(AU10,AW10)) | AY10: 0 | AZ10: 0 | BA10: 0 | BB10: =IF(B10="","",IF(AR10="No",AV10-AZ10,"")) | BC10: =IF(B10="","",IF(AR10="Yes",AS10-BA10,"")) | BD10: Quarterly | BE10: IT Services | BF10: USD | BG10: United States | BH10: No | BI10: =IF(B10="","",IF(OR(AND(AZ10>0,BB10>=2.5%,BB10<4%),AND(BA10>0,BC10>=6%,BC10<8%)),"Yes","No")) | BJ10: =IF(B10="","",IF(OR(AND(AZ10>0,BB10<2.5%),AND(BA10>0,BC10<6%)),"Yes","No")) | BK10: No | BL10: No | BM10: No | BN10: No | BO10: No | BP10: No | BQ10: No | BR10: No | BS10: No | BT10: No | BU10: No | BV10: No | BW10: No | BX10: No | BY10: No | BZ10: No | CA10: Yes | CB10: =IF(B10="","",IF(AT10="No",((BB10+AW10)-$AZ$4),((BB10+AX10)-$AZ$4))*IF(DD10>0,0,M10)) | CC10: =IF(B10="","",AY10*(L10-M10)*IF(DD10>0,0,1)) | CE10: =IF(AND(B10<>"",R10<=85%),1,0) | CF10: =IF(B10="",0,(IF(OR(BF10="USD",BF10="CAD",BF10="GBP",BF10="AUD",BF10="EUR"),0,1))) | CG10: =IF(B10="",0,(IF(OR(BG10="United States",BG10="Canada",BG10="United Kingdom",BG10="Australia",BG10="Netherlands Antilles",BG10="Bermuda",BG10="Cayman Islands",BG10="British Virgin Islands",BG10="Channel Islands",BG10="Isle of Man",BG10="Australia",BG10="Netherlands",BG10="Germany",BG10="Sweden",BG10="Switzerland",BG10="Austria",BG10="Belgium",BG10="Denmark",BG10="Finland",BG10="Iceland",BG10="Ireland",BG10="Lichtenstein",BG10="Luxemborg",BG10="Norway"),0,1))) | CH10: =IF(BN10="Yes",1,0) | CI10: =IF(BO10="Yes",1,0) | CJ10: =IF(BP10="Yes",1,0) | CK10: =IF(BQ10="Yes",1,0) | CL10: =IF(BR10="Yes",1,0) | CM10: =IF(BS10="Yes",1,0) | CN10: =IF(OR(AND(BJ10="Yes",N10="No"),AND(BJ10="Yes",N10="Yes",P10>=6)),1,0) | CO10: =IF(BT10="Yes",1,0) | CP10: =IF(AND(BU10="Yes",BV10="No"),1,0) | CQ10: =IF(BW10="Yes",1,0) | CR10: =IF(AP10="",0,IF(AP10>7,1,0)) | CS10: =IF(OR(BD10<>"Monthly",BD10<>"Quarterly",BD10<>"Semi-Annually"),0,1) | CT10: =IF(BX10="Yes",1,0) | CU10: =IF(BY10="Yes",1,0) | CV10: =IF(BZ10="Yes",1,0) | CW10: =IF(CA10="No",1,0) | CX10: =IF(B10="",0,IF(AK10>=5000000,0,1)) | CY10: =IF(B10="",0,IF(AL10>=5000000,0,1)) | CZ10: =IF(OR(DA10=1,DB10=1,DC10=1),0,IF(B10="",0,IF(OR(AND(AN10="Tier 1",X10="No",OR(AI10>$AJ$3,AJ10>$AJ$4)),(AND(AN10="Tier 1",X10="Yes",AJ10>$AJ$5)),(AND(AN10="Tier 2",X10="No",OR(AI10>$AK$3,AJ10>$AK$4))),(AND(AN10="Tier 2",X10="Yes",AJ10>$AK$5)),(AND(AN10="Tier 3",X10="No",OR(AI10>$AL$3,AJ10>$AL$4))),(AND(AN10="Tier 3",X10="Yes",AJ10>$AL$5))),1,0))) | DA10: =IF(OR(DB10=1,DC10=1),0,IF(B10="",0,IF(OR(AND(AN10="Tier 1",X10="No",OR(AI10>$AM$3,AJ10>$AM$4)),(AND(AN10="Tier 1",X10="Yes",AJ10>$AM$5)),(AND(AN10="Tier 2",X10="No",OR(AI10>$AN$3,AJ10>$AN$4))),(AND(AN10="Tier 2",X10="Yes",AJ10>$AN$5)),(AND(AN10="Tier 3",X10="No",OR(AI10>$AO$3,AJ10>$AO$4))),(AND(AN10="Tier 3",X10="Yes",AJ10>$AO$5))),1,0))) | DB10: =IF(DC10=1,0,IF(B10="",0,IF(OR(AND(AN10="Tier 1",X10="No",OR(AI10>$AP$3,AJ10>$AP$4)),(AND(AN10="Tier 1",X10="Yes",AJ10>$AP$5)),(AND(AN10="Tier 2",X10="No",OR(AI10>$AQ$3,AJ10>$AQ$4))),(AND(AN10="Tier 2",X10="Yes",AJ10>$AQ$5)),(AND(AN10="Tier 3",X10="No",OR(AI10>$AR$3,AJ10>$AR$4))),(AND(AN10="Tier 3",X10="Yes",AJ10>$AR$5))),1,0))) | DC10: =IF(B10="",0,IF(OR(AND(AN10="Tier 1",X10="No",OR(AI10>$AS$3,AJ10>$AS$4)),(AND(AN10="Tier 1",X10="Yes",AJ10>$AS$5)),(AND(AN10="Tier 2",X10="No",OR(AI10>$AT$3,AJ10>$AT$4))),(AND(AN10="Tier 2",X10="Yes",AJ10>$AT$5)),(AND(AN10="Tier 3",X10="No",OR(AI10>$AU$3,AJ10>$AU$4))),(AND(AN10="Tier 3",X10="Yes",AJ10>$AU$5))),1,0)) | DD10: =IF((SUM(CE10:CX10)=0),0,W10) | DE10: =IF(OR(B10="",DD10>0),0,W10) | DF10: =IF(B10="",0,IF(COUNTIF(CE10:CX10,1)>0,0,L10-M10)) | DG10: =DE10+IF(DD10>0,0,DF10) | DH10: =IF(B10="","",M10+DF10) | DI10: =IF(B10="",0,J10-K10) | DJ10: =IF(OR(BF10="EUR",BF10="CAD",BF10="GBP",BF10="AUD"),(GA10*(1-V10))+(HG10)+IF(HX10="",0,HX10*(1-U10)),0) | DK10: =IF(BF10="EUR",33%,IF(BF10="CAD",38%,IF(BF10="GBP",51%,IF(BF10="AUD",61%,0)))) | DL10: =DJ10*DK10 | DN10: =IF(OR(Y10="Second Lien",Y10="Tier 1 Split Lien",Y10="Tier 2 Split Lien"),DG10,0) | DO10: =DN10*DN$6 | DP10: =DG10-DO10 | DQ10: =IF(Y10="Second Lien",DP10,0) | DR10: =DQ10*DQ$6 | DS10: =DP10-DR10 | DT10: =IF(BH10="Yes",DS10,0) | DU10: =DT10*DT$6 | DV10: =DS10-DU10 | DW10: =IF(OR(BG10="Canada",BG10="United Kingdom",BG10="Australia",BG10="Netherlands Antilles",BG10="Bermuda",BG10="Cayman Islands",BG10="British Virgin Islands",BG10="Channel Islands",BG10="Isle of Man",BG10="Australia",BG10="Netherlands",BG10="Germany",BG10="Sweden",BG10="Switzerland",BG10="Austria",BG10="Belgium",BG10="Denmark",BG10="Finland",BG10="Iceland",BG10="Ireland",BG10="Lichtenstein",BG10="Luxemborg",BG10="Norway"),DV10,0) | DX10: =DW10*DW$6 | DY10: =DV10-DX10 | DZ10: =IF(BI10="Yes",DY10,0) | EA10: =DZ10*DZ$6 | EB10: =DY10-EA10 | EC10: =IF(OR(Z10="Delayed Draw",Z10="Revolver"),EB10,0) | ED10: =EC10*EC$6 | EE10: =EB10-ED10 | EF10: =IF(S10="Yes",EE10,0) | EG10: =EF10*EF$6 | EH10: =EE10-EG10 | EI10: =IF(Q10="Yes",EH10,0) | EJ10: =EI10*EI$6 | EK10: =EH10-EJ10 | EL10: =IF(BD10="Semi-Annually",EK10,0) | EM10: =EL10*EL$6 | EN10: =EK10-EM10 | EO10: =IF(BK10="Yes",EN10,0) | EP10: =EO10*EO$6 | EQ10: =EN10-EP10 | ER10: =IF(BL10="Yes",EQ10,0) | ES10: =ER10*ER$6 | ET10: =EQ10-ES10 | EU10: =IF(BM10="Yes",ET10,0) | EV10: =EU10*EU$6 | EW10: =ET10-EV10 | EX10: =IF(BV10="Yes",EW10,0) | EY10: =EX10*EX$6 | EZ10: =EW10-EY10 | FA10: =IF(AR10="Yes",EZ10,0) | FB10: =FA10*FA$6 | FC10: =EZ10-FB10 | FD10: =IF(OR(BF10="EUR",BF10="AUD",BF10="CAD",BF10="GBP"),FC10,0) | FE10: =FD10*FD$6 | FF10: =FC10-FE10 | FG10: =FF10 | FH10: =IF(FF10=0,0,VLOOKUP(C10,$GU$10:$GV$406,2,FALSE)*FF10) | FI10: =FF10-FH10 | FJ10: =FI10 | FK10: =IF(OR(IB10="",FI10<0.01),,VLOOKUP(IB10,$GL$10:$GM$406,2,FALSE)*FI10) | FL10: =FI10-FK10 | FM10: =FL10 | FN10: =IF(FL10=0,0,VLOOKUP(C10,$HD$10:$HE$406,2,FALSE)*FL10) | FO10: =FL10-FN10 | FP10: =IF(SUM(CY10:DC10)>0,0,IF(AND(AL10>=5000000,AL10<7500000),FO10,0)) | FQ10: =IF(B10="",0,FP10*FP$6*(1-$U10)) | FR10: =FO10-FQ10 | FS10: =IF(SUM(CY10:DC10)>0,0,IF(AL10<15000000,FR10,0)) | FT10: =IF(B10="",0,FS10*FS$6*(1-$U10)) | FU10: =FR10-FT10 | FV10: =IF(SUM(CY10:DC10)>0,0,IF(OR(AND(X10="No",AN10="Tier 1",AI10>$AG$3),AND(X10="No",AN10="Tier 2",AI10>$AH$3),AND(X10="No",AN10="Tier 3",AI10>$AI$3)),FU10,0)) | FW10: =IF(SUM(CY10:DC10)>0,0,IF(OR(AND(X10="No",AN10="Tier 1",AJ10>$AG$4),AND(X10="No",AN10="Tier 2",AJ10>$AH$4),AND(X10="No",AN10="Tier 3",AJ10>$AI$4)),FU10,0)) | FX10: =IF(SUM(CY10:DC10)>0,0,IF(OR(AND(X10="Yes",AN10="Tier 1",AJ10>$AG$5),AND(X10="Yes",AN10="Tier 2",AJ10>$AH$5),AND(X10="Yes",AN10="Tier 3",AJ10>$AI$5)),FU10,0)) | FY10: =IF(SUM(FV10:FX10)>0,FU10,0) | FZ10: =IF(B10="",0,FY10*FV$6*(1-MIN(90%,T10))) | GA10: =FU10-FZ10 | GB10: =IF(AND(N10="No",DI10=0),GA10,IF(AND(N10="No",DI10<>0,K10=0),0,IF(AND(N10="No",DI10<>0,K10>0,J10<>K10),MAX(0,M10-(DH10-GA10)),DG10))) | GC10: =+GB10*V10 | GD10: =IFERROR(GC10/K10,"") | GE10: =IF(IB10="","",IB10) | GF10: {=IF(SUM(IF(IB$9:IB9=IB10,1,0))>0,0,SUMIF($IB$10:$IB$406,IB10,$FI$10:$FI$406))} | GG10: =GF10 | GH10: 1 | GI10: =LARGE($GG$10:$GG$406,GH10) | GJ10: =IF(GH10>GH$6,0,IF(GH10=$GH$2,$GJ$2,IF(GH10<4,$GJ$3,$GJ$4))) | GK10: =MAX(0,GI10-GJ10) | GL10: {=IF(GI10=0,0,LARGE(IF($GF$10:$GF$406=GI10,$GE$10:$GE$406,0),COUNTIF($GI$10:$GI$406,GI10)-COUNTIF(GI$9:GI9,GI10)))} | GM10: =IF(GI10=0,0,GK10/GI10) | GO10: 1 | GP10: =IF(COUNTIF($A$10:A10,A10)<=1,SUMIF($A$10:$A$406,A10,$FG$10:$FG$406),0) | GQ10: 1 | GR10: =LARGE($GP$10:$GP$406,GQ10) | GS10: =IF(GQ10>GQ$6,0,IF(GQ10<=GQ$2,GS$2,IF(AND(GQ10<=$GQ$3,GQ10>$GQ$2),GS$3,GS$4))) | GT10: =MAX(0,GR10-GS10) | GU10: {=IF(GR10=0,0,LARGE(IF($GP$10:$GP$406=GR10,$GO$10:$GO$406,0),COUNTIF($GR$10:$GR$406,GR10)-COUNTIF(GR$9:GR9,GR10)))} | GV10: =IF(GR10=0,0,GT10/GR10) | GX10: 1 | GY10: =IF(COUNTIF($A$10:A10,A10)<=1,SUMIF($A$10:$A$406,A10,$FG$10:$FG$406),0) | GZ10: 1 | HA10: =LARGE($GY$10:$GY$406,GZ10) | HB10: - | HC10: =IF(GZ10<6,MAX(0,$HC$2/5),0) | HD10: {=IF(HA10=0,0,LARGE(IF($GY$10:$GY$406=HA10,$GX$10:$GX$406,0),COUNTIF($HA$10:$HA$406,HA10)-COUNTIF(HA$9:HA9,HA10)))} | HE10: =IF(HA10=0,0,HC10/HA10) | HG10: =DG10-GA10 | HH10: 0 | HI10: =MIN(HH10,DE10) | HK10: 1 | HL10: =SUMIF($C$10:$C$406,HK10,$DG$10:$DG$406) | HN10: =MIN(HO10:HS10) | HO10: =IF(B10="","",$M10) | HP10: =IF($N10="Yes",IF(P10>=6,0,MIN($T10*$M10,$U10*$M10)),"") | HQ10: =IF(AND(N10="Yes",P10>=6),"",IF($S10="Yes",$R10*$M10,"")) | HR10: =IF($Q10="Yes",MIN($M10,$T10*$M10),"") | HS10: =IF(AND($N10="Yes",$P10>=6),"",IF(OR(CY10=1,DC10=1,),MIN($T10*$M10,$U10*$M10),IF(OR(CZ10=1,DA10=1,DB10=1),IF(AK10>=5000000,MIN($T10*$M10,$IE10*$M10),MIN($T10*$M10,$U10*$M10)),""))) | HT10: =IF(DD10>0,DD10,"") | HU10: =IF(B10="",0,$L10-$M10) | HV10: =IF(OR(SUM(HP10:HT10)>0,P10>=6),"",IF($B10="","",1)) | HW10: =IF(AND($HT10<>0,OR(HT10<=MIN(HP10:HS10),SUM(HP10:HS10)=0)),$HT10,0) | HX10: =IF(AND($HS10<>0,OR(AND($HS10<>$HT10,$HS10<>$HR10,$HS10<>$HQ10,$HS10<>$HP10,$HS10<MIN($HP10:$HR10),$HS10<HT10),SUM($HP10:$HR10)+SUM(HT10)=0),IA10<=0),$HS10,0) | HY10: =IF(AND($HR10<>0,OR(AND($HR10<>$HT10,$HR10<>$HS10,$HR10<>$HQ10,$HR10<>$HP10),$HR10<MIN($HP10:$HQ10),$HR10<MIN($HS10:$HT10),SUM($HP10:$HQ10)+SUM($HS10:$HT10)=0)),$HR10,0) | HZ10: =IF(AND($HQ10<>0,OR(AND($HQ10<>$HT10,HQ10<>HS10,HQ10<>HR10,HQ10<>HP10,HQ10<MIN(HR10:HT10)),SUM(HP10)+SUM(HR10:HT10)=0)),$HQ10,0) | IA10: =IF(AND($HP10<>0,OR(HP10<=MIN(HQ10:HT10),SUM(HQ10:HT10)=0)),$HP10,0) | IB10: 41 | IC10: =HU10=DF10 | IE10: =IF(B10="","",IF(AND(Y10="Second Lien",OR(CZ10=1,DA10=1,DB10=1)),50%,IF(CZ10=1,90%,IF(DA10=1,80%,IF(DB10=1,65%,"No Initial Haircut")))))
A11: =D11 | B11: =IF(D11="","",B10+1) | C11: =IF(COUNTIF($A$10:A10,A11)>0,C10,C10+1) | D11: Cedar Ridge Holdings, LLC | E11: Cedar Ridge (Term Loan) | G11: 6009486.5 | H11: 6009486.5 | I11: 1 | J11: =IF(B11="","",G11*I11) | K11: =IF(B11="","",H11*I11) | L11: =IF(B11="","",IF(COUNTIF($CE11:$CX11,1)>0,0,J11)) | M11: =IF(B11="","",IF(COUNTIF($CE11:$CX11,1)>0,0,K11)) | N11: No | O11: N/A | P11: =IF(B11="","",IF(OR(O11="N/A",O11=""),0,YEARFRAC('Borrowing Base'!$J$4,'Loan List'!O11)*12)) | Q11: No | R11: 0.9975 | S11: =IF(B11="","",IF(R11<95%,"Yes","No")) | T11: 0.995 | U11: =IF(B11="","",IF(OR(Y11="First Lien",Y11="Split First Lien",Y11="Tier 1 Split Lien",Y11="Tier 2 Split Lien"),50%,30%)) | V11: =IF(B11="",0,IF(AND(Y11="First Lien",AN11="Tier 1"),IF(AND(X11="Yes",MIN(AH11,$AJ$5)>4.5),(((4.5/MIN(AH11,$AJ$5))*72.5%)+(((MIN(AH11,$AJ$5)-4.5)/MIN(AH11,$AJ$5))*35%)),72.5%),IF(AND(Y11="First Lien",AN11="Tier 2"),IF(AND(X11="Yes",MIN(AH11,$AK$5)>4.5),(((4.5/MIN(AH11,$AK$5))*72.5%)+(((MIN(AH11,$AK$5)-4.5)/MIN(AH11,$AK$5))*35%)),72.5%),IF(AND(X11="Yes",MIN(AH11,$AL$5)>4),(((4/MIN(AH11,$AL$5))*72.5%)+(((MIN(AH11,$AL$5)-4)/MIN(AH11,$AL$5))*35%)),IF(OR(Y11="First Lien",Y11="Split First Lien"),72.5%,IF(Y11="Split Lien", 53%,35%)))))) | W11: =IF($C11="","",MIN($HO11:$HS11)) | X11: Yes | Y11: First Lien | Z11: Term | AA11: NR | AB11: NR | AC11: 2.68 | AD11: 3.76 | AE11: 4.3704657 | AF11: 0.42754938 | AG11: 3.76 | AH11: 3.76 | AI11: 4.3704657 | AJ11: 4.3704657 | AK11: 35900000 | AL11: 61779000 | AM11: 45747 | AN11: =IF(C11="","",(IF(AK11>=50000000,"Tier 1",(IF(OR(AK11>=20000000,AND(AK11>5000000,AC11>=1.25,AF11<=0.65)),"Tier 2","Tier 3"))))) | AO11: 48149 | AP11: 6.2444444 | AQ11: =IF(C11="","",AP11) | AR11: No | AS11: 0 | AT11: Yes | AU11: 0.01 | AV11: 0.05 | AW11: 0.043079 | AX11: =IF(C11="","",MAX(AU11,AW11)) | AY11: 0 | AZ11: 0 | BA11: 0 | BB11: =IF(B11="","",IF(AR11="No",AV11-AZ11,"")) | BC11: =IF(B11="","",IF(AR11="Yes",AS11-BA11,"")) | BD11: Quarterly | BE11: Aerospace & Defense | BF11: USD | BG11: United States | BH11: No | BI11: =IF(B11="","",IF(OR(AND(AZ11>0,BB11>=2.5%,BB11<4%),AND(BA11>0,BC11>=6%,BC11<8%)),"Yes","No")) | BJ11: =IF(B11="","",IF(OR(AND(AZ11>0,BB11<2.5%),AND(BA11>0,BC11<6%)),"Yes","No")) | BK11: No | BL11: No | BM11: No | BN11: No | BO11: No | BP11: No | BQ11: No | BR11: No | BS11: No | BT11: No | BU11: No | BV11: No | BW11: No | BX11: No | BY11: No | BZ11: No | CA11: Yes | CB11: =IF(B11="","",IF(AT11="No",((BB11+AW11)-$AZ$4),((BB11+AX11)-$AZ$4))*IF(DD11>0,0,M11)) | CC11: =IF(B11="","",AY11*(L11-M11)*IF(DD11>0,0,1)) | CE11: =IF(AND(B11<>"",R11<=85%),1,0) | CF11: =IF(B11="",0,(IF(OR(BF11="USD",BF11="CAD",BF11="GBP",BF11="AUD",BF11="EUR"),0,1))) | CG11: =IF(B11="",0,(IF(OR(BG11="United States",BG11="Canada",BG11="United Kingdom",BG11="Australia",BG11="Netherlands Antilles",BG11="Bermuda",BG11="Cayman Islands",BG11="British Virgin Islands",BG11="Channel Islands",BG11="Isle of Man",BG11="Australia",BG11="Netherlands",BG11="Germany",BG11="Sweden",BG11="Switzerland",BG11="Austria",BG11="Belgium",BG11="Denmark",BG11="Finland",BG11="Iceland",BG11="Ireland",BG11="Lichtenstein",BG11="Luxemborg",BG11="Norway"),0,1))) | CH11: =IF(BN11="Yes",1,0) | CI11: =IF(BO11="Yes",1,0) | CJ11: =IF(BP11="Yes",1,0) | CK11: =IF(BQ11="Yes",1,0) | CL11: =IF(BR11="Yes",1,0) | CM11: =IF(BS11="Yes",1,0) | CN11: =IF(OR(AND(BJ11="Yes",N11="No"),AND(BJ11="Yes",N11="Yes",P11>=6)),1,0) | CO11: =IF(BT11="Yes",1,0) | CP11: =IF(AND(BU11="Yes",BV11="No"),1,0) | CQ11: =IF(BW11="Yes",1,0) | CR11: =IF(AP11="",0,IF(AP11>7,1,0)) | CS11: =IF(OR(BD11<>"Monthly",BD11<>"Quarterly",BD11<>"Semi-Annually"),0,1) | CT11: =IF(BX11="Yes",1,0) | CU11: =IF(BY11="Yes",1,0) | CV11: =IF(BZ11="Yes",1,0) | CW11: =IF(CA11="No",1,0) | CX11: =IF(B11="",0,IF(AK11>=5000000,0,1)) | CY11: =IF(B11="",0,IF(AL11>=5000000,0,1)) | CZ11: =IF(OR(DA11=1,DB11=1,DC11=1),0,IF(B11="",0,IF(OR(AND(AN11="Tier 1",X11="No",OR(AI11>$AJ$3,AJ11>$AJ$4)),(AND(AN11="Tier 1",X11="Yes",AJ11>$AJ$5)),(AND(AN11="Tier 2",X11="No",OR(AI11>$AK$3,AJ11>$AK$4))),(AND(AN11="Tier 2",X11="Yes",AJ11>$AK$5)),(AND(AN11="Tier 3",X11="No",OR(AI11>$AL$3,AJ11>$AL$4))),(AND(AN11="Tier 3",X11="Yes",AJ11>$AL$5))),1,0))) | DA11: =IF(OR(DB11=1,DC11=1),0,IF(B11="",0,IF(OR(AND(AN11="Tier 1",X11="No",OR(AI11>$AM$3,AJ11>$AM$4)),(AND(AN11="Tier 1",X11="Yes",AJ11>$AM$5)),(AND(AN11="Tier 2",X11="No",OR(AI11>$AN$3,AJ11>$AN$4))),(AND(AN11="Tier 2",X11="Yes",AJ11>$AN$5)),(AND(AN11="Tier 3",X11="No",OR(AI11>$AO$3,AJ11>$AO$4))),(AND(AN11="Tier 3",X11="Yes",AJ11>$AO$5))),1,0))) | DB11: =IF(DC11=1,0,IF(B11="",0,IF(OR(AND(AN11="Tier 1",X11="No",OR(AI11>$AP$3,AJ11>$AP$4)),(AND(AN11="Tier 1",X11="Yes",AJ11>$AP$5)),(AND(AN11="Tier 2",X11="No",OR(AI11>$AQ$3,AJ11>$AQ$4))),(AND(AN11="Tier 2",X11="Yes",AJ11>$AQ$5)),(AND(AN11="Tier 3",X11="No",OR(AI11>$AR$3,AJ11>$AR$4))),(AND(AN11="Tier 3",X11="Yes",AJ11>$AR$5))),1,0))) | DC11: =IF(B11="",0,IF(OR(AND(AN11="Tier 1",X11="No",OR(AI11>$AS$3,AJ11>$AS$4)),(AND(AN11="Tier 1",X11="Yes",AJ11>$AS$5)),(AND(AN11="Tier 2",X11="No",OR(AI11>$AT$3,AJ11>$AT$4))),(AND(AN11="Tier 2",X11="Yes",AJ11>$AT$5)),(AND(AN11="Tier 3",X11="No",OR(AI11>$AU$3,AJ11>$AU$4))),(AND(AN11="Tier 3",X11="Yes",AJ11>$AU$5))),1,0)) | DD11: =IF((SUM(CE11:CX11)=0),0,W11) | DE11: =IF(OR(B11="",DD11>0),0,W11) | DF11: =IF(B11="",0,IF(COUNTIF(CE11:CX11,1)>0,0,L11-M11)) | DG11: =DE11+IF(DD11>0,0,DF11) | DH11: =IF(B11="","",M11+DF11) | DI11: =IF(B11="",0,J11-K11) | DJ11: =IF(OR(BF11="EUR",BF11="CAD",BF11="GBP",BF11="AUD"),(GA11*(1-V11))+(HG11)+IF(HX11="",0,HX11*(1-U11)),0) | DK11: =IF(BF11="EUR",33%,IF(BF11="CAD",38%,IF(BF11="GBP",51%,IF(BF11="AUD",61%,0)))) | DL11: =DJ11*DK11 | DN11: =IF(OR(Y11="Second Lien",Y11="Tier 1 Split Lien",Y11="Tier 2 Split Lien"),DG11,0) | DO11: =DN11*DN$6 | DP11: =DG11-DO11 | DQ11: =IF(Y11="Second Lien",DP11,0) | DR11: =DQ11*DQ$6 | DS11: =DP11-DR11 | DT11: =IF(BH11="Yes",DS11,0) | DU11: =DT11*DT$6 | DV11: =DS11-DU11 | DW11: =IF(OR(BG11="Canada",BG11="United Kingdom",BG11="Australia",BG11="Netherlands Antilles",BG11="Bermuda",BG11="Cayman Islands",BG11="British Virgin Islands",BG11="Channel Islands",BG11="Isle of Man",BG11="Australia",BG11="Netherlands",BG11="Germany",BG11="Sweden",BG11="Switzerland",BG11="Austria",BG11="Belgium",BG11="Denmark",BG11="Finland",BG11="Iceland",BG11="Ireland",BG11="Lichtenstein",BG11="Luxemborg",BG11="Norway"),DV11,0) | DX11: =DW11*DW$6 | DY11: =DV11-DX11 | DZ11: =IF(BI11="Yes",DY11,0) | EA11: =DZ11*DZ$6 | EB11: =DY11-EA11 | EC11: =IF(OR(Z11="Delayed Draw",Z11="Revolver"),EB11,0) | ED11: =EC11*EC$6 | EE11: =EB11-ED11 | EF11: =IF(S11="Yes",EE11,0) | EG11: =EF11*EF$6 | EH11: =EE11-EG11 | EI11: =IF(Q11="Yes",EH11,0) | EJ11: =EI11*EI$6 | EK11: =EH11-EJ11 | EL11: =IF(BD11="Semi-Annually",EK11,0) | EM11: =EL11*EL$6 | EN11: =EK11-EM11 | EO11: =IF(BK11="Yes",EN11,0) | EP11: =EO11*EO$6 | EQ11: =EN11-EP11 | ER11: =IF(BL11="Yes",EQ11,0) | ES11: =ER11*ER$6 | ET11: =EQ11-ES11 | EU11: =IF(BM11="Yes",ET11,0) | EV11: =EU11*EU$6 | EW11: =ET11-EV11 | EX11: =IF(BV11="Yes",EW11,0) | EY11: =EX11*EX$6 | EZ11: =EW11-EY11 | FA11: =IF(AR11="Yes",EZ11,0) | FB11: =FA11*FA$6 | FC11: =EZ11-FB11 | FD11: =IF(OR(BF11="EUR",BF11="AUD",BF11="CAD",BF11="GBP"),FC11,0) | FE11: =FD11*FD$6 | FF11: =FC11-FE11 | FG11: =FF11 | FH11: =IF(FF11=0,0,VLOOKUP(C11,$GU$10:$GV$406,2,FALSE)*FF11) | FI11: =FF11-FH11 | FJ11: =FI11 | FK11: =IF(OR(IB11="",FI11<0.01),,VLOOKUP(IB11,$GL$10:$GM$406,2,FALSE)*FI11) | FL11: =FI11-FK11 | FM11: =FL11 | FN11: =IF(FL11=0,0,VLOOKUP(C11,$HD$10:$HE$406,2,FALSE)*FL11) | FO11: =FL11-FN11 | FP11: =IF(SUM(CY11:DC11)>0,0,IF(AND(AL11>=5000000,AL11<7500000),FO11,0)) | FQ11: =IF(B11="",0,FP11*FP$6*(1-$U11)) | FR11: =FO11-FQ11 | FS11: =IF(SUM(CY11:DC11)>0,0,IF(AL11<15000000,FR11,0)) | FT11: =IF(B11="",0,FS11*FS$6*(1-$U11)) | FU11: =FR11-FT11 | FV11: =IF(SUM(CY11:DC11)>0,0,IF(OR(AND(X11="No",AN11="Tier 1",AI11>$AG$3),AND(X11="No",AN11="Tier 2",AI11>$AH$3),AND(X11="No",AN11="Tier 3",AI11>$AI$3)),FU11,0)) | FW11: =IF(SUM(CY11:DC11)>0,0,IF(OR(AND(X11="No",AN11="Tier 1",AJ11>$AG$4),AND(X11="No",AN11="Tier 2",AJ11>$AH$4),AND(X11="No",AN11="Tier 3",AJ11>$AI$4)),FU11,0)) | FX11: =IF(SUM(CY11:DC11)>0,0,IF(OR(AND(X11="Yes",AN11="Tier 1",AJ11>$AG$5),AND(X11="Yes",AN11="Tier 2",AJ11>$AH$5),AND(X11="Yes",AN11="Tier 3",AJ11>$AI$5)),FU11,0)) | FY11: =IF(SUM(FV11:FX11)>0,FU11,0) | FZ11: =IF(B11="",0,FY11*FV$6*(1-MIN(90%,T11))) | GA11: =FU11-FZ11 | GB11: =IF(AND(N11="No",DI11=0),GA11,IF(AND(N11="No",DI11<>0,K11=0),0,IF(AND(N11="No",DI11<>0,K11>0,J11<>K11),MAX(0,M11-(DH11-GA11)),DG11))) | GC11: =+GB11*V11 | GD11: =IFERROR(GC11/K11,"") | GE11: =IF(IB11="","",IB11) | GF11: {=IF(SUM(IF(IB$9:IB10=IB11,1,0))>0,0,SUMIF($IB$10:$IB$406,IB11,$FI$10:$FI$406))} | GG11: =GF11 | GH11: =GH10+1 | GI11: =LARGE($GG$10:$GG$406,GH11) | GJ11: =IF(GH11>GH$6,0,IF(GH11=$GH$2,$GJ$2,IF(GH11<4,$GJ$3,$GJ$4))) | GK11: =MAX(0,GI11-GJ11) | GL11: {=IF(GI11=0,0,LARGE(IF($GF$10:$GF$406=GI11,$GE$10:$GE$406,0),COUNTIF($GI$10:$GI$406,GI11)-COUNTIF(GI$9:GI10,GI11)))} | GM11: =IF(GI11=0,0,GK11/GI11) | GO11: =IF(C11="","",IF(ISERROR(MATCH(C11,C10:C$10,0)),MAX(GO10:GO$10)+1,INDEX(GO10:GO$10,MATCH(C11,C10:C$10,0)))) | GP11: =IF(COUNTIF($A$10:A11,A11)<=1,SUMIF($A$10:$A$406,A11,$FG$10:$FG$406),0) | GQ11: =GQ10+1 | GR11: =LARGE($GP$10:$GP$406,GQ11) | GS11: =IF(GQ11>GQ$6,0,IF(GQ11<=GQ$2,GS$2,IF(AND(GQ11<=$GQ$3,GQ11>$GQ$2),GS$3,GS$4))) | GT11: =MAX(0,GR11-GS11) | GU11: {=IF(GR11=0,0,LARGE(IF($GP$10:$GP$406=GR11,$GO$10:$GO$406,0),COUNTIF($GR$10:$GR$406,GR11)-COUNTIF(GR$9:GR10,GR11)))} | GV11: =IF(GR11=0,0,GT11/GR11) | GX11: =IF(C11="","",IF(ISERROR(MATCH(C11,C10:C$10,0)),MAX(GO10:GO$10)+1,INDEX(GO10:GO$10,MATCH(C11,C10:C$10,0)))) | GY11: =IF(COUNTIF($A$10:A11,A11)<=1,SUMIF($A$10:$A$406,A11,$FG$10:$FG$406),0) | GZ11: =GZ10+1 | HA11: =LARGE($GY$10:$GY$406,GZ11) | HB11: - | HC11: =IF(GZ11<6,MAX(0,$HC$2/5),0) | HD11: {=IF(HA11=0,0,LARGE(IF($GY$10:$GY$406=HA11,$GX$10:$GX$406,0),COUNTIF($HA$10:$HA$406,HA11)-COUNTIF(HA$9:HA10,HA11)))} | HE11: =IF(HA11=0,0,HC11/HA11) | HG11: =DG11-GA11 | HH11: 0 | HI11: =MIN(HH11,DE11) | HK11: =IF(COUNTIF($C$10:$C$406,HK10+1),HK10+1,"") | HL11: =SUMIF($C$10:$C$406,HK11,$DG$10:$DG$406) | HN11: =MIN(HO11:HS11) | HO11: =IF(B11="","",$M11) | HP11: =IF($N11="Yes",IF(P11>=6,0,MIN($T11*$M11,$U11*$M11)),"") | HQ11: =IF(AND(N11="Yes",P11>=6),"",IF($S11="Yes",$R11*$M11,"")) | HR11: =IF($Q11="Yes",MIN($M11,$T11*$M11),"") | HS11: =IF(AND($N11="Yes",$P11>=6),"",IF(OR(CY11=1,DC11=1,),MIN($T11*$M11,$U11*$M11),IF(OR(CZ11=1,DA11=1,DB11=1),IF(AK11>=5000000,MIN($T11*$M11,$IE11*$M11),MIN($T11*$M11,$U11*$M11)),""))) | HT11: =IF(DD11>0,DD11,"") | HU11: =IF(B11="",0,$L11-$M11) | HV11: =IF(OR(SUM(HP11:HT11)>0,P11>=6),"",IF($B11="","",1)) | HW11: =IF(AND($HT11<>0,OR(HT11<=MIN(HP11:HS11),SUM(HP11:HS11)=0)),$HT11,0) | HX11: =IF(AND($HS11<>0,OR(AND($HS11<>$HT11,$HS11<>$HR11,$HS11<>$HQ11,$HS11<>$HP11,$HS11<MIN($HP11:$HR11),$HS11<HT11),SUM($HP11:$HR11)+SUM(HT11)=0),IA11<=0),$HS11,0) | HY11: =IF(AND($HR11<>0,OR(AND($HR11<>$HT11,$HR11<>$HS11,$HR11<>$HQ11,$HR11<>$HP11),$HR11<MIN($HP11:$HQ11),$HR11<MIN($HS11:$HT11),SUM($HP11:$HQ11)+SUM($HS11:$HT11)=0)),$HR11,0) | HZ11: =IF(AND($HQ11<>0,OR(AND($HQ11<>$HT11,HQ11<>HS11,HQ11<>HR11,HQ11<>HP11,HQ11<MIN(HR11:HT11)),SUM(HP11)+SUM(HR11:HT11)=0)),$HQ11,0) | IA11: =IF(AND($HP11<>0,OR(HP11<=MIN(HQ11:HT11),SUM(HQ11:HT11)=0)),$HP11,0) | IB11: 1 | IC11: =HU11=DF11 | IE11: =IF(B11="","",IF(AND(Y11="Second Lien",OR(CZ11=1,DA11=1,DB11=1)),50%,IF(CZ11=1,90%,IF(DA11=1,80%,IF(DB11=1,65%,"No Initial Haircut")))))
A12: =D12 | B12: =IF(D12="","",B11+1) | C12: =IF(COUNTIF($A$10:A11,A12)>0,C11,C11+1) | D12: Bluewater Holdings, LLC | E12: Bluewater (Term Loan) | G12: 5271860.2 | H12: 5271860.2 | I12: 1 | J12: =IF(B12="","",G12*I12) | K12: =IF(B12="","",H12*I12) | L12: =IF(B12="","",IF(COUNTIF($CE12:$CX12,1)>0,0,J12)) | M12: =IF(B12="","",IF(COUNTIF($CE12:$CX12,1)>0,0,K12)) | N12: No | O12: N/A | P12: =IF(B12="","",IF(OR(O12="N/A",O12=""),0,YEARFRAC('Borrowing Base'!$J$4,'Loan List'!O12)*12)) | Q12: No | R12: 0.99000524 | S12: =IF(B12="","",IF(R12<95%,"Yes","No")) | T12: 1 | U12: =IF(B12="","",IF(OR(Y12="First Lien",Y12="Split First Lien",Y12="Tier 1 Split Lien",Y12="Tier 2 Split Lien"),50%,30%)) | V12: =IF(B12="",0,IF(AND(Y12="First Lien",AN12="Tier 1"),IF(AND(X12="Yes",MIN(AH12,$AJ$5)>4.5),(((4.5/MIN(AH12,$AJ$5))*72.5%)+(((MIN(AH12,$AJ$5)-4.5)/MIN(AH12,$AJ$5))*35%)),72.5%),IF(AND(Y12="First Lien",AN12="Tier 2"),IF(AND(X12="Yes",MIN(AH12,$AK$5)>4.5),(((4.5/MIN(AH12,$AK$5))*72.5%)+(((MIN(AH12,$AK$5)-4.5)/MIN(AH12,$AK$5))*35%)),72.5%),IF(AND(X12="Yes",MIN(AH12,$AL$5)>4),(((4/MIN(AH12,$AL$5))*72.5%)+(((MIN(AH12,$AL$5)-4)/MIN(AH12,$AL$5))*35%)),IF(OR(Y12="First Lien",Y12="Split First Lien"),72.5%,IF(Y12="Split Lien", 53%,35%)))))) | W12: =IF($C12="","",MIN($HO12:$HS12)) | X12: No | Y12: First Lien | Z12: Term | AA12: NR | AB12: NR | AC12: 1.633068 | AD12: 3.4364287 | AE12: 3.5785077 | AF12: 0.48220859 | AG12: 3.4364287 | AH12: 3.4364287 | AI12: 3.8376355 | AJ12: 3.8376355 | AK12: 11436291 | AL12: 15496061 | AM12: 45838 | AN12: =IF(C12="","",(IF(AK12>=50000000,"Tier 1",(IF(OR(AK12>=20000000,AND(AK12>5000000,AC12>=1.25,AF12<=0.65)),"Tier 2","Tier 3"))))) | AO12: 47358 | AP12: 4.0777778 | AQ12: =IF(C12="","",AP12) | AR12: No | AS12: 0 | AT12: Yes | AU12: 0.01 | AV12: 0.0575 | AW12: 0.042956 | AX12: =IF(C12="","",MAX(AU12,AW12)) | AY12: 0 | AZ12: 0 | BA12: 0 | BB12: =IF(B12="","",IF(AR12="No",AV12-AZ12,"")) | BC12: =IF(B12="","",IF(AR12="Yes",AS12-BA12,"")) | BD12: Quarterly | BE12: Diversified Financial Services | BF12: USD | BG12: United States | BH12: No | BI12: =IF(B12="","",IF(OR(AND(AZ12>0,BB12>=2.5%,BB12<4%),AND(BA12>0,BC12>=6%,BC12<8%)),"Yes","No")) | BJ12: =IF(B12="","",IF(OR(AND(AZ12>0,BB12<2.5%),AND(BA12>0,BC12<6%)),"Yes","No")) | BK12: No | BL12: No | BM12: No | BN12: No | BO12: No | BP12: No | BQ12: No | BR12: No | BS12: No | BT12: No | BU12: No | BV12: No | BW12: No | BX12: No | BY12: No | BZ12: No | CA12: Yes | CB12: =IF(B12="","",IF(AT12="No",((BB12+AW12)-$AZ$4),((BB12+AX12)-$AZ$4))*IF(DD12>0,0,M12)) | CC12: =IF(B12="","",AY12*(L12-M12)*IF(DD12>0,0,1)) | CE12: =IF(AND(B12<>"",R12<=85%),1,0) | CF12: =IF(B12="",0,(IF(OR(BF12="USD",BF12="CAD",BF12="GBP",BF12="AUD",BF12="EUR"),0,1))) | CG12: =IF(B12="",0,(IF(OR(BG12="United States",BG12="Canada",BG12="United Kingdom",BG12="Australia",BG12="Netherlands Antilles",BG12="Bermuda",BG12="Cayman Islands",BG12="British Virgin Islands",BG12="Channel Islands",BG12="Isle of Man",BG12="Australia",BG12="Netherlands",BG12="Germany",BG12="Sweden",BG12="Switzerland",BG12="Austria",BG12="Belgium",BG12="Denmark",BG12="Finland",BG12="Iceland",BG12="Ireland",BG12="Lichtenstein",BG12="Luxemborg",BG12="Norway"),0,1))) | CH12: =IF(BN12="Yes",1,0) | CI12: =IF(BO12="Yes",1,0) | CJ12: =IF(BP12="Yes",1,0) | CK12: =IF(BQ12="Yes",1,0) | CL12: =IF(BR12="Yes",1,0) | CM12: =IF(BS12="Yes",1,0) | CN12: =IF(OR(AND(BJ12="Yes",N12="No"),AND(BJ12="Yes",N12="Yes",P12>=6)),1,0) | CO12: =IF(BT12="Yes",1,0) | CP12: =IF(AND(BU12="Yes",BV12="No"),1,0) | CQ12: =IF(BW12="Yes",1,0) | CR12: =IF(AP12="",0,IF(AP12>7,1,0)) | CS12: =IF(OR(BD12<>"Monthly",BD12<>"Quarterly",BD12<>"Semi-Annually"),0,1) | CT12: =IF(BX12="Yes",1,0) | CU12: =IF(BY12="Yes",1,0) | CV12: =IF(BZ12="Yes",1,0) | CW12: =IF(CA12="No",1,0) | CX12: =IF(B12="",0,IF(AK12>=5000000,0,1)) | CY12: =IF(B12="",0,IF(AL12>=5000000,0,1)) | CZ12: =IF(OR(DA12=1,DB12=1,DC12=1),0,IF(B12="",0,IF(OR(AND(AN12="Tier 1",X12="No",OR(AI12>$AJ$3,AJ12>$AJ$4)),(AND(AN12="Tier 1",X12="Yes",AJ12>$AJ$5)),(AND(AN12="Tier 2",X12="No",OR(AI12>$AK$3,AJ12>$AK$4))),(AND(AN12="Tier 2",X12="Yes",AJ12>$AK$5)),(AND(AN12="Tier 3",X12="No",OR(AI12>$AL$3,AJ12>$AL$4))),(AND(AN12="Tier 3",X12="Yes",AJ12>$AL$5))),1,0))) | DA12: =IF(OR(DB12=1,DC12=1),0,IF(B12="",0,IF(OR(AND(AN12="Tier 1",X12="No",OR(AI12>$AM$3,AJ12>$AM$4)),(AND(AN12="Tier 1",X12="Yes",AJ12>$AM$5)),(AND(AN12="Tier 2",X12="No",OR(AI12>$AN$3,AJ12>$AN$4))),(AND(AN12="Tier 2",X12="Yes",AJ12>$AN$5)),(AND(AN12="Tier 3",X12="No",OR(AI12>$AO$3,AJ12>$AO$4))),(AND(AN12="Tier 3",X12="Yes",AJ12>$AO$5))),1,0))) | DB12: =IF(DC12=1,0,IF(B12="",0,IF(OR(AND(AN12="Tier 1",X12="No",OR(AI12>$AP$3,AJ12>$AP$4)),(AND(AN12="Tier 1",X12="Yes",AJ12>$AP$5)),(AND(AN12="Tier 2",X12="No",OR(AI12>$AQ$3,AJ12>$AQ$4))),(AND(AN12="Tier 2",X12="Yes",AJ12>$AQ$5)),(AND(AN12="Tier 3",X12="No",OR(AI12>$AR$3,AJ12>$AR$4))),(AND(AN12="Tier 3",X12="Yes",AJ12>$AR$5))),1,0))) | DC12: =IF(B12="",0,IF(OR(AND(AN12="Tier 1",X12="No",OR(AI12>$AS$3,AJ12>$AS$4)),(AND(AN12="Tier 1",X12="Yes",AJ12>$AS$5)),(AND(AN12="Tier 2",X12="No",OR(AI12>$AT$3,AJ12>$AT$4))),(AND(AN12="Tier 2",X12="Yes",AJ12>$AT$5)),(AND(AN12="Tier 3",X12="No",OR(AI12>$AU$3,AJ12>$AU$4))),(AND(AN12="Tier 3",X12="Yes",AJ12>$AU$5))),1,0)) | DD12: =IF((SUM(CE12:CX12)=0),0,W12) | DE12: =IF(OR(B12="",DD12>0),0,W12) | DF12: =IF(B12="",0,IF(COUNTIF(CE12:CX12,1)>0,0,L12-M12)) | DG12: =DE12+IF(DD12>0,0,DF12) | DH12: =IF(B12="","",M12+DF12) | DI12: =IF(B12="",0,J12-K12) | DJ12: =IF(OR(BF12="EUR",BF12="CAD",BF12="GBP",BF12="AUD"),(GA12*(1-V12))+(HG12)+IF(HX12="",0,HX12*(1-U12)),0) | DK12: =IF(BF12="EUR",33%,IF(BF12="CAD",38%,IF(BF12="GBP",51%,IF(BF12="AUD",61%,0)))) | DL12: =DJ12*DK12 | DN12: =IF(OR(Y12="Second Lien",Y12="Tier 1 Split Lien",Y12="Tier 2 Split Lien"),DG12,0) | DO12: =DN12*DN$6 | DP12: =DG12-DO12 | DQ12: =IF(Y12="Second Lien",DP12,0) | DR12: =DQ12*DQ$6 | DS12: =DP12-DR12 | DT12: =IF(BH12="Yes",DS12,0) | DU12: =DT12*DT$6 | DV12: =DS12-DU12 | DW12: =IF(OR(BG12="Canada",BG12="United Kingdom",BG12="Australia",BG12="Netherlands Antilles",BG12="Bermuda",BG12="Cayman Islands",BG12="British Virgin Islands",BG12="Channel Islands",BG12="Isle of Man",BG12="Australia",BG12="Netherlands",BG12="Germany",BG12="Sweden",BG12="Switzerland",BG12="Austria",BG12="Belgium",BG12="Denmark",BG12="Finland",BG12="Iceland",BG12="Ireland",BG12="Lichtenstein",BG12="Luxemborg",BG12="Norway"),DV12,0) | DX12: =DW12*DW$6 | DY12: =DV12-DX12 | DZ12: =IF(BI12="Yes",DY12,0) | EA12: =DZ12*DZ$6 | EB12: =DY12-EA12 | EC12: =IF(OR(Z12="Delayed Draw",Z12="Revolver"),EB12,0) | ED12: =EC12*EC$6 | EE12: =EB12-ED12 | EF12: =IF(S12="Yes",EE12,0) | EG12: =EF12*EF$6 | EH12: =EE12-EG12 | EI12: =IF(Q12="Yes",EH12,0) | EJ12: =EI12*EI$6 | EK12: =EH12-EJ12 | EL12: =IF(BD12="Semi-Annually",EK12,0) | EM12: =EL12*EL$6 | EN12: =EK12-EM12 | EO12: =IF(BK12="Yes",EN12,0) | EP12: =EO12*EO$6 | EQ12: =EN12-EP12 | ER12: =IF(BL12="Yes",EQ12,0) | ES12: =ER12*ER$6 | ET12: =EQ12-ES12 | EU12: =IF(BM12="Yes",ET12,0) | EV12: =EU12*EU$6 | EW12: =ET12-EV12 | EX12: =IF(BV12="Yes",EW12,0) | EY12: =EX12*EX$6 | EZ12: =EW12-EY12 | FA12: =IF(AR12="Yes",EZ12,0) | FB12: =FA12*FA$6 | FC12: =EZ12-FB12 | FD12: =IF(OR(BF12="EUR",BF12="AUD",BF12="CAD",BF12="GBP"),FC12,0) | FE12: =FD12*FD$6 | FF12: =FC12-FE12 | FG12: =FF12 | FH12: =IF(FF12=0,0,VLOOKUP(C12,$GU$10:$GV$406,2,FALSE)*FF12) | FI12: =FF12-FH12 | FJ12: =FI12 | FK12: =IF(OR(IB12="",FI12<0.01),,VLOOKUP(IB12,$GL$10:$GM$406,2,FALSE)*FI12) | FL12: =FI12-FK12 | FM12: =FL12 | FN12: =IF(FL12=0,0,VLOOKUP(C12,$HD$10:$HE$406,2,FALSE)*FL12) | FO12: =FL12-FN12 | FP12: =IF(SUM(CY12:DC12)>0,0,IF(AND(AL12>=5000000,AL12<7500000),FO12,0)) | FQ12: =IF(B12="",0,FP12*FP$6*(1-$U12)) | FR12: =FO12-FQ12 | FS12: =IF(SUM(CY12:DC12)>0,0,IF(AL12<15000000,FR12,0)) | FT12: =IF(B12="",0,FS12*FS$6*(1-$U12)) | FU12: =FR12-FT12 | FV12: =IF(SUM(CY12:DC12)>0,0,IF(OR(AND(X12="No",AN12="Tier 1",AI12>$AG$3),AND(X12="No",AN12="Tier 2",AI12>$AH$3),AND(X12="No",AN12="Tier 3",AI12>$AI$3)),FU12,0)) | FW12: =IF(SUM(CY12:DC12)>0,0,IF(OR(AND(X12="No",AN12="Tier 1",AJ12>$AG$4),AND(X12="No",AN12="Tier 2",AJ12>$AH$4),AND(X12="No",AN12="Tier 3",AJ12>$AI$4)),FU12,0)) | FX12: =IF(SUM(CY12:DC12)>0,0,IF(OR(AND(X12="Yes",AN12="Tier 1",AJ12>$AG$5),AND(X12="Yes",AN12="Tier 2",AJ12>$AH$5),AND(X12="Yes",AN12="Tier 3",AJ12>$AI$5)),FU12,0)) | FY12: =IF(SUM(FV12:FX12)>0,FU12,0) | FZ12: =IF(B12="",0,FY12*FV$6*(1-MIN(90%,T12))) | GA12: =FU12-FZ12 | GB12: =IF(AND(N12="No",DI12=0),GA12,IF(AND(N12="No",DI12<>0,K12=0),0,IF(AND(N12="No",DI12<>0,K12>0,J12<>K12),MAX(0,M12-(DH12-GA12)),DG12))) | GC12: =+GB12*V12 | GD12: =IFERROR(GC12/K12,"") | GE12: =IF(IB12="","",IB12) | GF12: {=IF(SUM(IF(IB$9:IB11=IB12,1,0))>0,0,SUMIF($IB$10:$IB$406,IB12,$FI$10:$FI$406))} | GG12: =GF12 | GH12: =GH11+1 | GI12: =LARGE($GG$10:$GG$406,GH12) | GJ12: =IF(GH12>GH$6,0,IF(GH12=$GH$2,$GJ$2,IF(GH12<4,$GJ$3,$GJ$4))) | GK12: =MAX(0,GI12-GJ12) | GL12: {=IF(GI12=0,0,LARGE(IF($GF$10:$GF$406=GI12,$GE$10:$GE$406,0),COUNTIF($GI$10:$GI$406,GI12)-COUNTIF(GI$9:GI11,GI12)))} | GM12: =IF(GI12=0,0,GK12/GI12) | GO12: =IF(C12="","",IF(ISERROR(MATCH(C12,C$10:C11,0)),MAX(GO$10:GO11)+1,INDEX(GO$10:GO11,MATCH(C12,C$10:C11,0)))) | GP12: =IF(COUNTIF($A$10:A12,A12)<=1,SUMIF($A$10:$A$406,A12,$FG$10:$FG$406),0) | GQ12: =GQ11+1 | GR12: =LARGE($GP$10:$GP$406,GQ12) | GS12: =IF(GQ12>GQ$6,0,IF(GQ12<=GQ$2,GS$2,IF(AND(GQ12<=$GQ$3,GQ12>$GQ$2),GS$3,GS$4))) | GT12: =MAX(0,GR12-GS12) | GU12: {=IF(GR12=0,0,LARGE(IF($GP$10:$GP$406=GR12,$GO$10:$GO$406,0),COUNTIF($GR$10:$GR$406,GR12)-COUNTIF(GR$9:GR11,GR12)))} | GV12: =IF(GR12=0,0,GT12/GR12) | GX12: =IF(C12="","",IF(ISERROR(MATCH(C12,C$10:C11,0)),MAX(GO$10:GO11)+1,INDEX(GO$10:GO11,MATCH(C12,C$10:C11,0)))) | GY12: =IF(COUNTIF($A$10:A12,A12)<=1,SUMIF($A$10:$A$406,A12,$FG$10:$FG$406),0) | GZ12: =GZ11+1 | HA12: =LARGE($GY$10:$GY$406,GZ12) | HB12: - | HC12: =IF(GZ12<6,MAX(0,$HC$2/5),0) | HD12: {=IF(HA12=0,0,LARGE(IF($GY$10:$GY$406=HA12,$GX$10:$GX$406,0),COUNTIF($HA$10:$HA$406,HA12)-COUNTIF(HA$9:HA11,HA12)))} | HE12: =IF(HA12=0,0,HC12/HA12) | HG12: =DG12-GA12 | HH12: 0 | HI12: =MIN(HH12,DE12) | HK12: =IF(COUNTIF($C$10:$C$406,HK11+1),HK11+1,"") | HL12: =SUMIF($C$10:$C$406,HK12,$DG$10:$DG$406) | HN12: =MIN(HO12:HS12) | HO12: =IF(B12="","",$M12) | HP12: =IF($N12="Yes",IF(P12>=6,0,MIN($T12*$M12,$U12*$M12)),"") | HQ12: =IF(AND(N12="Yes",P12>=6),"",IF($S12="Yes",$R12*$M12,"")) | HR12: =IF($Q12="Yes",MIN($M12,$T12*$M12),"") | HS12: =IF(AND($N12="Yes",$P12>=6),"",IF(OR(CY12=1,DC12=1,),MIN($T12*$M12,$U12*$M12),IF(OR(CZ12=1,DA12=1,DB12=1),IF(AK12>=5000000,MIN($T12*$M12,$IE12*$M12),MIN($T12*$M12,$U12*$M12)),""))) | HT12: =IF(DD12>0,DD12,"") | HU12: =IF(B12="",0,$L12-$M12) | HV12: =IF(OR(SUM(HP12:HT12)>0,P12>=6),"",IF($B12="","",1)) | HW12: =IF(AND($HT12<>0,OR(HT12<=MIN(HP12:HS12),SUM(HP12:HS12)=0)),$HT12,0) | HX12: =IF(AND($HS12<>0,OR(AND($HS12<>$HT12,$HS12<>$HR12,$HS12<>$HQ12,$HS12<>$HP12,$HS12<MIN($HP12:$HR12),$HS12<HT12),SUM($HP12:$HR12)+SUM(HT12)=0),IA12<=0),$HS12,0) | HY12: =IF(AND($HR12<>0,OR(AND($HR12<>$HT12,$HR12<>$HS12,$HR12<>$HQ12,$HR12<>$HP12),$HR12<MIN($HP12:$HQ12),$HR12<MIN($HS12:$HT12),SUM($HP12:$HQ12)+SUM($HS12:$HT12)=0)),$HR12,0) | HZ12: =IF(AND($HQ12<>0,OR(AND($HQ12<>$HT12,HQ12<>HS12,HQ12<>HR12,HQ12<>HP12,HQ12<MIN(HR12:HT12)),SUM(HP12)+SUM(HR12:HT12)=0)),$HQ12,0) | IA12: =IF(AND($HP12<>0,OR(HP12<=MIN(HQ12:HT12),SUM(HQ12:HT12)=0)),$HP12,0) | IB12: 20 | IC12: =HU12=DF12 | IE12: =IF(B12="","",IF(AND(Y12="Second Lien",OR(CZ12=1,DA12=1,DB12=1)),50%,IF(CZ12=1,90%,IF(DA12=1,80%,IF(DB12=1,65%,"No Initial Haircut")))))
