Workbook
Name a: #REF!
Name a: #REF!
Name AUGUST: #REF!
Name AUGUST: #REF!
Name CAPSTOCK: #REF!
Name CAPSTOCK: #REF!
Name CASHREC: #REF!
Name CASHREC: #REF!
Name check1: #REF!
Name check1: #REF!
Name CHECKLIST: #REF!
Name CHECKLIST: #REF!
Name cklst: [3]Chklst!$A$1:$C$26
Name CLASSEXP: #REF!
Name CLASSEXP: #REF!
Name COST: #REF!
Name COST: #REF!
Name COST2: #REF!
Name COST2: #REF!
Name Days: '[4]Cost Rollforward - PTO'!$C$45
Name Days_2: '[5]Cost Roll'!$C$52
Name DERIVATIVE: #REF!
Name DERIVATIVE: #REF!
Name DETAIL: #REF!
Name DETAIL: #REF!
Name DISTREC: #REF!
Name DISTREC: #REF!
Name DISTRIBUTION: #REF!
Name DISTRIBUTION: #REF!
Name DVD: #REF!
Name DVD: #REF!
Name DVDII: #REF!
Name DVDII: #REF!
Name EntityNames: [6]EntityLookup!$A$3:$A$5
Name EXPENSES: #REF!
Name EXPENSES: #REF!
Name Facility_Name: '[7]PAR Settled'!$B:$B
Name fadfs: '[8]Cost Roll'!$C$24
Name FAX: #REF!
Name FAX: #REF!
Name foursixtythree: #REF!
Name foursixtythree: #REF!
Name GAIN: #REF!
Name GAIN: #REF!
Name Gain_Loss_01: #REF!
Name Gain_Loss_01: #REF!
Name Gain_Loss_02: #REF!
Name Gain_Loss_02: #REF!
Name Gain_Loss_03: #REF!
Name Gain_Loss_03: #REF!
Name Gain_Loss_04: #REF!
Name Gain_Loss_04: #REF!
Name Gain_Loss_05: #REF!
Name Gain_Loss_05: #REF!
Name Gain_Loss_06: #REF!
Name Gain_Loss_06: #REF!
Name Gain_Loss_07: #REF!
Name Gain_Loss_07: #REF!
Name Gain_Loss_08: #REF!
Name Gain_Loss_08: #REF!

Sheet Inputs
A1: PENNANTPARK FLOATING RATE FUNDING I, LLC
A2: SERVICING REPORT
A4: Amounts are pro forma for proposed borrowing and related use of proceeds
A6: INPUTS
A8: Determination Date | J8: 45893
A9: Minimum Equity Amount Floor | J9: 30000000
A11: Exchange Rates
A12: USD | J12: 1
A13: CAD | J13: 0.72138
A14: AUD | J14: 0.64344
A15: EUR | J15: 1.1659
A17: Temporary Participation Pool Acquisition Date | J17: 45897

Sheet Borrowing Base
A1: PENNANTPARK FLOATING RATE FUNDING I, LLC
A2: BORROWING BASE CERTIFICATE
A3: Amounts are pro forma for proposed borrowing and related use of proceeds
A4: DETERMINATION DATE | J4: =Inputs!$J$8 -> 45893
A5: CONCENTRATION TEST AMOUNT | J5: ='Loan List'!DI6 -> 1.0192857e+09 | O5: Cash and Credit Facility Balance Projections
A8: BORROWING BASE - (A) minus (B) minus (A)(iv) | J8: =J10-J18-J14 -> 9.6501187e+08 | O8: AUD
K9: Check | O9: 0 | P9: Current Credit Facility Balance
B10: (A) | C10: Aggregate Collateral Balance (without duplication) sum of (i)-(vi) | J10: =SUM(J11:J16) -> 9.7268796e+08 | O10: =+O71 -> 0 | P10: Borrowing
C11: (i) Aggregate Principal Balance of all Collateral Loans (other than Defaulted, Restructured, Haircut Ineligible, and Discount) | J11: ='Loan List'!HW8 -> 8.6554057e+08 | O11: =SUM(O9:O10) -> 0 | P11: Projected Credit Facility Balance
C12: (ii) Defaulted Collateral Loan Balance | J12: ='Loan List'!IB8 -> 0 | O12: USD
C13: (iii) The aggregate purchase price of all Discount Loans that are Eligible Collateral Loans and not Defaulted, Haircut or Restructured | J13: ='Loan List'!IA8 -> 6259376.3 | O13: =325500000-20800000+23000000+3000000-12000000+1200000+6000000+9500000+7500000-3000000-17000000+5000000+15000000+4000000+35500000-13000000+19000000+5000000+6000000+3500000-27000000+18000000+10000000+5000000+5000000-10000000+17000000+19000000+13000000-200000000-6000000+4000000+4000000-10000000+8000000+18000000+10000000+16000000+5000000+21000000+27000000+40000000+5000000+15000000+16000000-27000000+15000000+8000000+15000000+18000000-54000000+20000000-58000000-23000000-43000000-15000000-46000000+10000000+10000000+7500000-6500000-115000000+32000000+46000000-81000000+8000000+50000000+12000000+69000000+11000000-80000000-50000000-25500000+11000000+20000000+10000000+10000000+20000000+20000000-5000000-65000000+20000000+60000000+30000000+20000000-35000000-7000000+10000000-40000000-50000000+30000000-48000000+20000000-45000000-35000000+15000000-35000000-55000000+15000000+160000000+75000000+50000000+30000000-130000000-42000000+50000000+55000000+40000000+50000000+80000000+20000000+100000000+20000000+25000000+50000000-320000000-30000000+20000000-55000000+25000000+20000000+75000000+70000000 -> 462400000 | P13: Current Credit Facility Balance
C14: (iv) The aggregate Unfunded Commitments of all Delayed Drawdown and Revolvers that are Eligible Loans | J14: ='Loan List'!HV8 -> 6719880.5 | O14: =+O33 -> 220000000 | P14: Borrowing
C15: (v) The Credit Improved Loan Balance | J15: ='Loan List'!HZ8 -> 0 | O15: =SUM(O13:O14) -> 682400000 | P15: Projected Credit Facility Balance
C16: (vi) The Haircut Collateral Loan Balance | J16: ='Loan List'!HY8 -> 94168133 | O16: CAD
O17: 2000000 | P17: Current Credit Facility Balance
B18: (B) | C18: Excess Concentration Amount | J18: ='Loan List'!HH6 -> 956213.27 | O18: 0 | P18: Borrowing
O19: =SUM(O17:O18) -> 2000000 | P19: Projected Credit Facility Balance
A20: MAXIMUM AVAILABLE AMOUNT - Least of (A), (B) and (C) | J20: =MIN(J27,J35,J40) -> 6.9232108e+08 | O20: EUR
O21: 0 | P21: Current Credit Facility Balance
C22: Least of: | O22: 0 | P22: Borrowing
O23: =SUM(O21:O22) -> 0 | P23: Projected Credit Facility Balance
B24: (A) | D24: Facility Amount, less | J24: 718000000
D25: Revolving Exposure, plus | J25: ='Loan List'!$DG$6 -> 6719880.5 | O25: =+O11*Inputs!J14+'Borrowing Base'!O15+'Borrowing Base'!O19*Inputs!J13+'Borrowing Base'!O23*Inputs!J15 -> 683842760
D26: Amount on deposit in the Revolving Reserve Account | J26: 0 | O26: =+J46-O25 -> 0 | P26: Check
J27: =J24-J25+J26 -> 7.1128012e+08
O28: =+J53 -> 8478317.6 | P28: Equity/Cushion
B29: (B) | C29: (i) | D29: (x) Borrowing Base, multipled by | J29: ='Borrowing Base'!J8 -> 9.6501187e+08 | O29: =+J18 -> 956213.27 | P29: Net Penalty
D30: (y) Weighted Average Advance Rate, minus | J30: ='Loan List'!AZ2 -> 0.71355359
C31: (ii) | D31: Foreign Currency Variability Reserve, minus | J31: ='Loan List'!DM6 -> 130314.39 | O31: USD
C32: (iii) | D32: Revolving Exposure, plus | J32: ='Loan List'!$DG$6 -> 6719880.5 | O32: 29681562 | P32: Cash - Current & PreBorrowing
C33: (iv) | D33: Cash on deposit in Principal Collection Subaccount | J33: =+O51+O59*Inputs!J13+'Borrowing Base'!O67*Inputs!J15+'Borrowing Base'!O75*Inputs!J14 -> 10583588 | O33: 220000000 | P33: Borrowing
C34: (v) | D34: Amount on deposit in the Revolving Reserve Account | J34: =J26 -> 0 | O34: =SUM(O32:O33) -> 2.4968156e+08 | P34: Cash - Budgeted & PostBorrowing
J35: =(J29*J30)-J31-J32+J33+J34 -> 6.9232108e+08 | O35: -189760365 | P35: Asset Purchases
O36: -49500000 | P36: NARS Purchase
B37: (C) | C37: (A) | D37: Aggregate Collateral Balance, minus | J37: =J10-J14 -> 9.6596808e+08
C38: (B) | D38: Minimum Equity Amount, plus | J38: =MAX(Inputs!J9,SUM(LARGE('Loan List'!$HM$10:$HM$406,1),LARGE('Loan List'!$HM$10:$HM$406,2),LARGE('Loan List'!$HM$10:$HM$406,3))) -> 128975161
C39: (C) | D39: Cash on deposit in Principal Collection Subaccount | J39: =J33 -> 10583588
J40: =J37-J38+J39 -> 8.4757651e+08
A42: ADVANCES OUTSTANDING
A44: Advances Outstanding at beginning of the Interest Accrual Period | J44: =+O13+O9*Inputs!J14+'Borrowing Base'!O17*Inputs!J13+'Borrowing Base'!O21*Inputs!J15 -> 463842760
...

Sheet Loan List
B1: ='Borrowing Base'!A1 -> PENNANTPARK FLOATING RATE FUNDING I, LLC | AG1: 20% Conc. Limit | AJ1: Level 1 - 10% Haircut | AM1: Level 2 - 20% Haircut | AP1: Level 3 - 35% Haircut | AS1: Level 4 - Max Eligibility - 50% Haircut | GI1: No of Industry | GJ1: Limit | GK1: Limit $ | GR1: No of Obligor | GS1: Limit % | GT1: Limit $ | HA1: No of Obligor | HB1: Limit % | HC1: Limit $ | HD1: Total Excess
B2: Loan List | AG2: Tier 1 Obligor | AH2: Tier 2 Obligor | AI2: Tier 3 Obligor | AJ2: Tier 1 Obligor | AK2: Tier 2 Obligor | AL2: Tier 3 Obligor | AM2: Tier 1 Obligor | AN2: Tier 2 Obligor | AO2: Tier 3 Obligor | AP2: Tier 1 Obligor | AQ2: Tier 2 Obligor | AR2: Tier 3 Obligor | AS2: Tier 1 Obligor | AT2: Tier 2 Obligor | AU2: Tier 3 Obligor | AY2: Weighted Average Advance Rate: | AZ2: =SUMPRODUCT(($GC10:$GC406>0)*$GC10:$GC406*$V10:$V406)/SUMPRODUCT(($GC10:$GC406>0)*$GC10:$GC406) -> 0.71355359 | DN2: Limit % | DO2: 0.15 | DR2: 0.1 | DU2: 0.05 | DX2: 0.15 | EA2: 0.1 | ED2: 0.15 | EG2: 0.1 | EJ2: 0.25 | EM2: 0.1 | EP2: 0.03 | ES2: 0.15 | EV2: 0.05 | EY2: 0.15 | FB2: 0.1 | FE2: 0.15 | FQ2: 0.05 | FT2: 0.2 | FW2: 0.2 | GI2: 1 | GJ2: 0.25 | GK2: ='Borrowing Base'!J5*GJ2 -> 2.5482142e+08 | GR2: 3 | GS2: 0.06666666 | GT2: ='Borrowing Base'!J5*GS2 -> 67952372 | HA2: 5 | HB2: 0.3 | HC2: =HB2*'Borrowing Base'!J5 -> 3.0578571e+08 | HD2: =MAX(0,SUM(HB10:HB11)-HC2) -> 0
B3: ="Loan Portfolio as of: "&TEXT(Inputs!$J$8,"mmmm d, yyyy") -> Loan Portfolio as of: August 24, 2025 | AF3: SD/EBITDA | AG3: 5 | AH3: 4.25 | AI3: 3.75 | AJ3: 5.5 | AK3: 4.75 | AL3: 4.25 | AM3: 6 | AN3: 5.25 | AO3: 4.75 | AP3: 6.5 | AQ3: 5.75 | AR3: 5.25 | AS3: 7 | AT3: 6.25 | AU3: 5.75 | AY3: Weighted Average Coupon: | AZ3: =IFERROR(SUMPRODUCT((AS10:AS406>0)*DH10:DH406*AS10:AS406)/SUMPRODUCT((AS10:AS406>0)*DH10:DH406),"N/A") -> N/A | DN3: Limit | DO3: =DO2*'Borrowing Base'!$J$5 -> 1.5289285e+08 | DR3: =DR2*'Borrowing Base'!$J$5 -> 1.0192857e+08 | DU3: =DU2*'Borrowing Base'!$J$5 -> 50964284 | DX3: =DX2*'Borrowing Base'!$J$5 -> 1.5289285e+08 | EA3: =EA2*'Borrowing Base'!$J$5 -> 1.0192857e+08 | ED3: =ED2*'Borrowing Base'!$J$5 -> 1.5289285e+08 | EG3: =EG2*'Borrowing Base'!$J$5 -> 1.0192857e+08 | EJ3: =EJ2*'Borrowing Base'!$J$5 -> 2.5482142e+08 | EM3: =EM2*'Borrowing Base'!$J$5 -> 1.0192857e+08 | EP3: =EP2*'Borrowing Base'!$J$5 -> 30578571 | ES3: =ES2*'Borrowing Base'!$J$5 -> 1.5289285e+08 | EV3: =EV2*'Borrowing Base'!$J$5 -> 50964284 | EY3: =EY2*'Borrowing Base'!$J$5 -> 1.5289285e+08 | FB3: =FB2*'Borrowing Base'!$J$5 -> 1.0192857e+08 | FE3: =FE2*'Borrowing Base'!$J$5 -> 1.5289285e+08 | FQ3: =FQ2*'Borrowing Base'!$J$5 -> 50964284 | FT3: =FT2*'Borrowing Base'!$J$5 -> 2.0385714e+08 | FW3: =FW2*'Borrowing Base'!$J$5 -> 2.0385714e+08 | GI3: 2 and 3 | GJ3: 0.15 | GK3: ='Borrowing Base'!J5*GJ3 -> 1.5289285e+08 | GR3: 5 | GS3: 0.06 | GT3: ='Borrowing Base'!J5*GS3 -> 61157141
AF4: TD/EBITDA | AG4: 7 | AH4: 6 | AI4: 5 | AJ4: 7.5 | AK4: 6.5 | AL4: 5.5 | AM4: 8 | AN4: 7 | AO4: 6 | AP4: 8.5 | AQ4: 7.5 | AR4: 6.5 | AS4: 9 | AT4: 8 | AU4: 7 | AY4: Specified Term SOFR: | AZ4: 0.0432224 | DN4: Total | DO4: =SUM(DO10:DO406) -> 1000000 | DR4: =SUM(DR10:DR406) -> 1000000 | DU4: =SUM(DU10:DU406) -> 0 | DX4: =SUM(DX10:DX406) -> 0 | EA4: =SUM(EA10:EA406) -> 15340518 | ED4: =SUM(ED10:ED406) -> 21097586 | EG4: =SUM(EG10:EG406) -> 14663827 | EJ4: =SUM(EJ10:EJ406) -> 0 | EM4: =SUM(EM10:EM406) -> 0 | EP4: =SUM(EP10:EP406) -> 0 | ES4: =SUM(ES10:ES406) -> 0 | EV4: =SUM(EV10:EV406) -> 0 | EY4: =SUM(EY10:EY406) -> 11464651 | FB4: =SUM(FB10:FB406) -> 0 | FE4: =SUM(FE10:FE406) -> 1232469.6 | FQ4: =SUM(FQ10:FQ406) -> 8000000 | FT4: =SUM(FT10:FT406) -> 79136453 | FW4: =SUM(FZ10:FZ406) -> 2.1341927e+08 | FX4: =SUM(FX10:FX406) -> 0 | FY4: =SUM(FY10:FY406) -> 62147861 | FZ4: =SUM(FZ10:FZ406) -> 2.1341927e+08 | GI4: Other | GJ4: 0.15 | GK4: ='Borrowing Base'!J5*GJ4 -> 1.5289285e+08 | GR4: All others | GS4: 0.05 | GT4: ='Borrowing Base'!J5*GS4 -> 50964284
AF5: UD/EBITDA | AG5: 6 | AH5: 5.25 | AI5: 4.5 | AJ5: 6.5 | AK5: 5.75 | AL5: 5 | AM5: 7 | AN5: 6.25 | AO5: 5.5 | AP5: 7.5 | AQ5: 6.75 | AR5: 6 | AS5: 8 | AT5: 7.25 | AU5: 6.5 | AV5: Weighted Average Life: | AW5: =SUMPRODUCT(AQ10:AQ406,$DH$10:$DH$406)/SUM($DH$10:$DH$406) -> 4.1797276 | AY5: Weighted Average Spread: | AZ5: =SUM($CC$10:$CD$406)/SUMIF($AR$10:$AR$406,"No",$DF$10:$DF$406) -> 0.058597603 | CY5: =SUM(CY10:CY406) -> 1 | CZ5: =SUM(CZ10:CZ406) -> 6 | DA5: =SUM(DA10:DA406) -> 24 | DB5: =SUM(DB10:DB406) -> 2 | DC5: =SUM(DC10:DC406) -> 1 | DD5: =SUM(DD10:DD406) -> 18 | DN5: Excess | DO5: =MAX(0,DO4-DO3) -> 0 | DR5: =MAX(0,DR4-DR3) -> 0 | DU5: =MAX(0,DU4-DU3) -> 0 | DX5: =MAX(0,DX4-DX3) -> 0 | EA5: =MAX(0,EA4-EA3) -> 0 | ED5: =MAX(0,ED4-ED3) -> 0 | EG5: =MAX(0,EG4-EG3) -> 0 | EJ5: =MAX(0,EJ4-EJ3) -> 0 | EM5: =MAX(0,EM4-EM3) -> 0 | EP5: =MAX(0,EP4-EP3) -> 0 | ES5: =MAX(0,ES4-ES3) -> 0 | EV5: =MAX(0,EV4-EV3) -> 0 | EY5: =MAX(0,EY4-EY3) -> 0 | FB5: =MAX(0,FB4-FB3) -> 0 | FE5: =MAX(0,FE4-FE3) -> 0 | FQ5: =MAX(0,FQ4-FQ3) -> 0 | FR5: Haircut Excess | FT5: =MAX(0,FT4-FT3) -> 0 | FU5: Haircut Excess | FW5: =MAX(0,SUM(FZ4:FZ4)-FW3) -> 9562132.7 | GA5: Haircut Excess | GH5: =COUNTIF(GG10:GG406,">"&0) -> 25 | GQ5: =COUNTIF(GQ10:GQ406,">"&0) -> 106 | GZ5: =COUNTIF(GZ10:GZ406,">"&0) -> 106
DF6: =SUM(DF10:DF406) -> 9.1115754e+08 | DG6: =SUM(DG10:DG406) -> 6719880.5 | DH6: =SUM(DH10:DH406) -> 9.1787742e+08 | DI6: =SUM(DI10:DI406) -> 1.0192857e+09 | DJ6: =SUM(DJ10:DJ406) -> 6719880.5 | DM6: =SUM(DM10:DM406) -> 130314.39 | DN6: Haircut | DO6: =IF(DO4<0.01,0,DO5/DO4) -> 0 | DP6: =SUM(DP10:DP406) -> 0 | DQ6: =SUM(DQ10:DQ406) -> 9.1787742e+08 | DR6: =IF(DR4<0.01,0,DR5/DR4) -> 0 | DS6: =SUM(DS10:DS406) -> 0 | DT6: =SUM(DT10:DT406) -> 9.1787742e+08 | DU6: =IF(DU4<0.01,0,DU5/DU4) -> 0 | DV6: =SUM(DV10:DV406) -> 0 | DW6: =SUM(DW10:DW406) -> 9.1787742e+08 | DX6: =IF(DX4<0.01,0,DX5/DX4) -> 0 | DY6: =SUM(DY10:DY406) -> 0 | DZ6: =SUM(DZ10:DZ406) -> 9.1787742e+08 | EA6: =IF(EA4<0.01,0,EA5/EA4) -> 0 | EB6: =SUM(EB10:EB406) -> 0 | EC6: =SUM(EC10:EC406) -> 9.1787742e+08 | ED6: =IF(ED4<0.01,0,ED5/ED4) -> 0 | EE6: =SUM(EE10:EE406) -> 0 | EF6: =SUM(EF10:EF406) -> 9.1787742e+08 | EG6: =IF(EG4<0.01,0,EG5/EG4) -> 0 | EH6: =SUM(EH10:EH406) -> 0 | EI6: =SUM(EI10:EI406) -> 9.1787742e+08 | EJ6: =IF(EJ4<0.01,0,EJ5/EJ4) -> 0 | EK6: =SUM(EK10:EK406) -> 0 | EL6: =SUM(EL10:EL406) -> 9.1787742e+08 | EM6: =IF(EM4<0.01,0,EM5/EM4) -> 0 | EN6: =SUM(EN10:EN406) -> 0 | EO6: =SUM(EO10:EO406) -> 9.1787742e+08 | EP6: =IF(EP4<0.01,0,EP5/EP4) -> 0 | EQ6: =SUM(EQ10:EQ406) -> 0 | ER6: =SUM(ER10:ER406) -> 9.1787742e+08 | ES6: =IF(ES4<0.01,0,ES5/ES4) -> 0 | ET6: =SUM(ET10:ET406) -> 0 | EU6: =SUM(EU10:EU406) -> 9.1787742e+08 | EV6: =IF(EV4<0.01,0,EV5/EV4) -> 0 | EW6: =SUM(EW10:EW406) -> 0 | EX6: =SUM(EX10:EX406) -> 9.1787742e+08 | EY6: =IF(EY4<0.01,0,EY5/EY4) -> 0 | EZ6: =SUM(EZ10:EZ406) -> 0 | FA6: =SUM(FA10:FA406) -> 9.1787742e+08 | FB6: =IF(FB4<0.01,0,FB5/FB4) -> 0 | FC6: =SUM(FC10:FC406) -> 0 | FD6: =SUM(FD10:FD406) -> 9.1787742e+08 | FE6: =IF(FE4<0.01,0,FE5/FE4) -> 0 | FF6: =SUM(FF10:FF406) -> 0 | FG6: =SUM(FG10:FG406) -> 9.1787742e+08 | FI6: =SUM(FI10:FI406) -> 0 | FJ6: =SUM(FJ10:FJ406) -> 9.1787742e+08 | FK6: =SUM(FK10:FK406) -> 9.1787742e+08 | FL6: =SUM(FL10:FL406) -> 0 | FM6: =SUM(FM10:FM406) -> 9.1787742e+08 | FO6: =SUM(FO10:FO406) -> 0 | FP6: =SUM(FP10:FP406) -> 9.1787742e+08 | FQ6: =IF(FQ4<0.01,0,FQ5/FQ4) -> 0 | FR6: =SUM(FR10:FR406) -> 0 | FS6: =SUM(FS10:FS406) -> 9.1787742e+08 | FT6: =IF(FT4<0.01,0,FT5/FT4) -> 0 | FU6: =SUM(FU10:FU406) -> 0 | FV6: =SUM(FV10:FV406) -> 9.1787742e+08 | FW6: =IF(SUM(FW4:FZ4)<0.01,0,FW5/SUM(FZ4:FZ4)) -> 0.044804449 | GA6: =SUM(GA10:GA406) -> 956213.27 | GB6: =SUM(GB10:GB406) -> 9.1692121e+08 | GC6: =SUM(GC10:GC406) -> 9.1022573e+08 | GD6: =SUM(GD10:GD406) -> 6.4949484e+08 | GH6: =SUM(GH10:GH406) -> 9.1787742e+08 | GI6: =GH5 -> 25 | GJ6: =SUM(GJ10:GJ406) -> 9.1787742e+08 | GL6: =SUM(GL10:GL406) -> 0 | GQ6: =SUM(GQ10:GQ406) -> 9.1787742e+08 | GR6: =GQ5 -> 106 | GS6: =SUM(GS10:GS406) -> 9.1787742e+08 | GU6: =SUM(GU10:GU406) -> 0 | GZ6: =SUM(GZ10:GZ406) -> 9.1787742e+08 | HA6: =GZ5 -> 106 | HB6: =SUM(HB10:HB406) -> 9.1787742e+08 | HD6: =SUM(HD10:HD406) -> 0 | HH6: =SUM(HH10:HH406) -> 956213.27 | HI6: =SUM(HI10:HI406) -> 0 | HV6: Eligible Unfunded
G7: =SUM(G10:G406) -> 1.0406533e+09 | H7: =SUM(H10:H406) -> 1.0339334e+09 | J7: =SUM(J10:J406) -> 1.0401773e+09 | K7: =SUM(K10:K406) -> 1.0334574e+09 | L7: =SUM(L10:L406) -> 1.0192857e+09 | M7: =SUM(M10:M406) -> 1.0125658e+09 | O7: =SUMIF(N10:N406,"Yes",K10:K406) -> 1701302.6 | W7: =SUM(W10:W406) -> 9.1115754e+08 | HT7: =SUM(HT10:HT406) -> 97553268
L8: Eligible Balances | N8: Loan Value Criteria | AA8: Credit/Performance Metrics | AR8: Interest Metrics | BE8: Other Loan Characteristics | BO8: Eligibility Criteria | CF8: Eligibility Criteria | DO8: Excess Concentrations | HO8: =SUM(HO10:HO406) -> 9.1115754e+08 | HP8: =SUM(HP10:HP406) -> 1.0125658e+09 | HV8: =SUMIF($HU$10:$HU$406,"",$HV$10:$HV$406) -> 6719880.5 | HW8: =SUMIF(HW10:HW406,"> 0",HP10:HP406) -> 8.6554057e+08 | HX8: =SUM(HX10:HX406) -> 0 | HY8: =SUM(HY10:HY406) -> 94168133 | HZ8: =SUM(HZ10:HZ406) -> 0 | IA8: =SUM(IA10:IA406) -> 6259376.3 | IB8: =SUM(IB10:IB406) -> 0
B9: Loan Number | C9: Obligor | D9: Obligor Name | E9: Security Name | F9: Purchase Date (Date Loan contributed to the facility) | G9: Total Commitment (Issue Currency) | H9: Outstanding Principal Balance (Issue Currency) | I9: Exchange Rate | J9: Total Commitment (USD) | K9: Outstanding Principal Balance (USD) | L9: Eligible Commitment (USD) | M9: Eligible Outstanding Principal Balance (USD) | N9: Defaulted Collateral Loan / Material Mod (Y/N) | O9: Date of Default | P9: Months Since Default | Q9: Credit Improved Loan (Y/N) | R9: Purchase Price | S9: Discount Collateral Loan (Y/N) | T9: Market Value | U9: Applicable Recovery Rate | V9: Advance Rate | W9: Aggregate Collateral Balance (Pre-Eligibility; Excluding Unfunded; Excluding Principal Acct) | X9: Stretch Senior Loan (Y/N) | Y9: Lien Type (First Lien / Split First Lien / Split Lien / Second Lien) | Z9: Loan Type (Term / Delayed Draw / Revolver) | AA9: Current Moody's Rating | AB9: Current S&P Rating | AC9: Initial Fixed Charge Coverage Ratio | AD9: Current Fixed Charge Coverage Ratio | AE9: Current Interest Coverage Ratio | AF9: Initial Debt to Capitalization Ratio | AG9: Initial Senior Debt/ EBITDA | AH9: Initial Total Debt/ EBITDA | AI9: Current Senior Debt/ EBITDA | AJ9: Current Total Debt/ EBITDA | AK9: Initial TTM EBITDA | AL9: Current TTM EBITDA | AM9: Current As of Date For Leverage and EBITDA | AN9: Tier 1 / Tier 2 Obligor | AO9: Maturity Date | AP9: Rem. Term to Maturity | AQ9: Avg Life | AR9: Fixed Rate (Y/N) | AS9: Coupon incl. PIK and PIK'able (if Fixed) | AT9: Floor Obligation (Y/N) | AU9: Floor | AV9: Spread incl. PIK and PIK'able | AW9: Base Rate | AX9: Greater of Base Rate and Floor | AY9: For Revolvers/Delayed Draw, commitment or other unused fee | AZ9: PIK / PIK'able For Floating Rate Loans | BA9: PIK / PIK'able For Fixed Rate Loans | BB9: Cash Spread On Floating Rate Loans | BC9: Cash Spread On Fixed Rate Loans | BD9: Interest Paid | BE9: Obligor Industry | BF9: Currency (USD / CAD / GBP / AUD / EUR) | BG9: Obligor Country | BH9: DIP Loan (Y/N) | BI9: Partial PIK Loan (Y/N) | BJ9: Non-Cash PIK Loan (Y/N) | BK9: Warrants to Purchase Equity (Y/N) | BL9: LBO Loan (Y/N) | BM9: Parti-cipation (Y/N) | BN9: Fifth Amendment Participation Pool | BO9: Convertible to Equity (Y/N) | BP9: Equity Security (Y/N) | BQ9: At Acquisition - Subject to offer or called for redemption (Y/N) | BR9: Margin Stock (Y/N) | BS9: Subject to withholding tax (Y/N) | BT9: At Acquisition - Defaulted Collateral Loan | BU9: Zero Coupon Obligation(Y/N) | BV9: Covenant Lite (Y/N) | BW9: Eligible Covenant Lite (Y/N) | BX9: Structured Finance Obligation, finance lease or chattel paper (Y/N) | BY9: Material Non-Credit Related Risk (Y/N) | BZ9: Primarily Secured by Real Estate, Construction Loan or Project Finance Loan (Y/N) | CA9: Interest Only Security (Y/N) | CB9: Satisfies all Other Eligibility Criteria (Y/N) | CC9: Aggregate Funded Spread | CD9: Aggregate Unfunded Spread | CF9: Purchased Below 85% of Par | CG9: Eligible Currency | CH9: Eligible Country | CI9: Convertible to Equity | CJ9: Equity Security | CK9: Subject to offer or called for redemption | CL9: Margin Stock | CM9: Subject to withholding tax | CN9: At Acquisition - Defaulted Collateral Loan | CO9: Non-cash PIK | CP9: Zero Coupon Obligation | CQ9: Covenant Lite | CR9: Structured Finance Obligation | CS9: Remaining term > 7 yrs | CT9: Interest Paid At Least Semi Annually | CU9: Material Non-Credit Related Risk | CV9: Real Estate, Construction or Project Finance Loan | CW9: Interest Only Security | CX9: Satisfies all Other Eligibility Criteria | CY9: EBITDA Requirement at Acquisition | CZ9: EBITDA Requirement Ongoing | DA9: Leverage 10% Haircut | DB9: Leverage 20% Haircut | DC9: Leverage 35% Haircut | DD9: Leverage - Final Haircut - 50% | DE9: Total Ineligible (excl. EBITDA and Leverage Ongoing) | DF9: Aggregate Collateral Balance (Post Eligibility; Including Haircut Ineligible; Excluding Unfunded) | DG9: Eligible Unfunded | DH9: Aggregate Collateral Balance (Post Eligibility; Including Eligible Unfunded) | DI9: Concentration Test Balance - OPB + Eligible Unfunded | DJ9: Revolving Exposure | DK9: Foreign Currency Loan OC Balance | DL9: Foreign Currency Variability Factor | DM9: Foreign Currency Variability Reserve | DO9: Second Lien and Split Lien | DP9: Excess | DQ9: Net Loan Balance | DR9: Second Lien | DS9: Excess | DT9: Net Loan Balance | DU9: DIP Collateral Loans | DV9: Excess | DW9: Net Loan Balance | DX9: Eligible Foreign Country | DY9: Excess | DZ9: Net Loan Balance | EA9: Partial PIK Loan | EB9: Excess | EC9: Net Loan Balance | ED9: Revolving / Delayed Drawdown | EE9: Excess | EF9: Net Loan Balance | EG9: Discount Loans | EH9: Excess | EI9: Net Loan Balance | EJ9: Credit Improved Loans | EK9: Excess | EL9: Net Loan Balance | EM9: Less than Quarterly Pay | EN9: Excess | EO9: Net Loan Balance | EP9: Warrants to Purchase Equity Securities | EQ9: Excess | ER9: Net Loan Balance | ES9: LBO Loan with Equity to Cap <25% | ET9: Excess | EU9: Net Loan Balance | EV9: Participation Interests | EW9: Excess | EX9: Net Loan Balance | EY9: Eligible Covenant Lite Loans | EZ9: Excess | FA9: Net Loan Balance | FB9: Fixed Rate Loan | FC9: Excess | FD9: Net Loan Balance | FE9: Agreed Foreign Currency | FF9: Excess | FG9: Net Loan Balance | FH9: Obligor | FI9: Excess | FJ9: Net Loan Balance | FK9: Obligor Industry | FL9: Excess | FM9: Net Loan Balance | FN9: Top 5 Obligors | FO9: Excess | FP9: Net Loan Balance | FQ9: LTM EBITDA >= 5,000,000 but < 7,500,000 | FR9: Excess; Haircut to 1-Recovery Rate | FS9: Net Loan Balance | FT9: LTM EBITDA < 15,000,000 | FU9: Excess; Haircut to 1-Recovery Rate | FV9: Net Loan Balance | FW9: LTM Snr Debt / EBITDA | FX9: LTM Total Debt / EBITDA | FY9: Stretch Senior LTM Total Debt / EBITDA | FZ9: Exceeds Leverage Limitation | GA9: Excess; Haircut to 1-Min(90% and Market Value) | GB9: Excess Concentration Test | GC9: Net Loan Balance | GD9: Borrowing Base | GF9: Industry No | GG9: Lookups'!F2:F3 Loan Balance | GH9: Industry Loan Balance | GI9: Industry Order | GJ9: Outstanding Loan Balance | GK9: Limit | GL9: Excess | GM9: Industry No (Matched) | GN9: Haircut | GP9: Obligor No | GQ9: Obligor Loan Balance | GR9: Obligor Order | GS9: Obligor Loan Balance | GT9: Limit | GU9: Excess | GV9: Obligor No | GW9: Haircut | GY9: Obligor No | GZ9: Obligor Loan Balance | HA9: Obligor Order | HB9: Obligor Loan Balance | HC9: Limit | HD9: Excess | HE9: Obligor No | HF9: Haircut | HH9: Excess Concentration Amount (Dynamic) | HI9: Excess Concentration Amount (HARD CODE on Last Day of Reinvestment Period) | HJ9: Applicable Excess Concentration Amount (Last Day of Reinvestment Period) | HL9: Obligor No | HM9: Obligor Loan Balance | HO9: Aggregate Collateral Balance (Pre-Eligibility; Excluding Unfunded; Excluding Principal Acct) | HP9: Outstanding Principal Balance | HQ9: Defaulted Collateral Loan Balance | HR9: Discount Loan Balance | HS9: Credit Improved Balance | HT9: Haircut Ineligible | HU9: Ineligibles | HV9: Total Unfunded | HW9: APB (Other Than Def, Inelib, Restructured, Haircut) | HX9: Ineligibles Test | HY9: Haircut Test | HZ9: Credit Improved Test | IA9: Discount Test | IB9: Defaulted Test | IC9: Lookups'!F2:F3 No | IF9: Initial Haircut Level
A10: ACP Avenu Buyer, LLC | B10: 1 | C10: 1 | D10: ACP Avenu Buyer, LLC | E10: Avenu (TL) | G10: 25589358 | H10: 25589358 | I10: =IF(B10="","",VLOOKUP(BF10,Inputs!$A$12:$J$15,10,FALSE)) -> 1 | J10: =IF(B10="","",G10*I10) -> 25589358 | K10: =IF(B10="","",H10*I10) -> 25589358 | L10: =IF(B10="","",IF(COUNTIF($CF10:$CY10,1)>0,0,J10)) -> 25589358 | M10: =IF(B10="","",IF(COUNTIF($CF10:$CY10,1)>0,0,K10)) -> 25589358 | N10: No | O10: N/A | P10: =IF(B10="","",IF(OR(O10="N/A",O10=""),0,YEARFRAC('Borrowing Base'!$J$4,'Loan List'!O10)*12)) -> 0 | Q10: No | R10: 0.99733768 | S10: =IF(B10="","",IF(R10<95%,"Yes","No")) -> No | T10: 0.99 | U10: =IF(B10="","",IF(OR(Y10="First Lien",Y10="Split First Lien",Y10="Tier 1 Split Lien",Y10="Tier 2 Split Lien"),50%,30%)) -> 0.5 | V10: =IF(B10="",0,IF(AND(Y10="First Lien",AN10="Tier 1"),IF(AND(X10="Yes",MIN(AH10,$AJ$5)>4.5),(((4.5/MIN(AH10,$AJ$5))*72.5%)+(((MIN(AH10,$AJ$5)-4.5)/MIN(AH10,$AJ$5))*35%)),72.5%),IF(AND(Y10="First Lien",AN10="Tier 2"),IF(AND(X10="Yes",MIN(AH10,$AK$5)>4.5),(((4.5/MIN(AH10,$AK$5))*72.5%)+(((MIN(AH10,$AK$5)-4.5)/MIN(AH10,$AK$5))*35%)),72.5%),IF(AND(X10="Yes",MIN(AH10,$AL$5)>4),(((4/MIN(AH10,$AL$5))*72.5%)+(((MIN(AH10,$AL$5)-4)/MIN(AH10,$AL$5))*35%)),IF(OR(Y10="First Lien",Y10="Split First Lien"),72.5%,IF(Y10="Split Lien", 53%,35%)))))) -> 0.67533071 | W10: =IF($C10="","",MIN($HP10:$HT10)) -> 25589358 | X10: Yes | Y10: First Lien | Z10: Term | AA10: NR | AB10: NR | AC10: 1.1174448 | AD10: 1.4275347 | AE10: 2.224929 | AF10: 0.4590766 | AG10: 5.1870295 | AH10: 5.1870295 | AI10: 4.6060902 | AJ10: 4.6060902 | AK10: 33738000 | AL10: 77650021 | AM10: 45747 | AN10: =IF(C10="","",(IF(AK10>=50000000,"Tier 1",(IF(OR(AK10>=20000000,AND(AK10>5000000,AC10>=1.25,AF10<=0.65)),"Tier 2","Tier 3"))))) -> Tier 2 | AO10: 47393 | AP10: =IF(C10="","",DAYS360(Inputs!$J$8,AO10)/360) -> 4.1055556 | AQ10: =IF(C10="","",AP10) -> 4.1055556 | AR10: No | AS10: 0 | AT10: Yes | AU10: 0.01 | AV10: 0.0475 | AW10: 0.042906 | AX10: =IF(C10="","",MAX(AU10,AW10)) -> 0.042906 | AY10: 0 | AZ10: 0 | BA10: 0 | BB10: =IF(B10="","",IF(AR10="No",AV10-AZ10,"")) -> 0.0475 | BC10: =IF(B10="","",IF(AR10="Yes",AS10-BA10,"")) | BD10: Quarterly | BE10: IT Services | BF10: USD | BG10: United States | BH10: No | BI10: =IF(B10="","",IF(OR(AND(AZ10>0,BB10>=2.5%,BB10<4%),AND(BA10>0,BC10>=6%,BC10<8%)),"Yes","No")) -> No | BJ10: =IF(B10="","",IF(OR(AND(AZ10>0,BB10<2.5%),AND(BA10>0,BC10<6%)),"Yes","No")) -> No | BK10: No | BL10: No | BM10: No | BN10: No | BO10: No | BP10: No | BQ10: No | BR10: No | BS10: No | BT10: No | BU10: No | BV10: No | BW10: No | BX10: No | BY10: No | BZ10: No | CA10: No | CB10: Yes | CC10: =IF(B10="","",IF(AT10="No",((BB10+AW10)-$AZ$4),((BB10+AX10)-$AZ$4))*IF(DE10>0,0,M10)) -> 1207398 | CD10: =IF(B10="","",AY10*(L10-M10)*IF(DE10>0,0,1)) -> 0 | CF10: =IF(AND(B10<>"",R10<=85%),1,0) -> 0 | CG10: =IF(B10="",0,(IF(OR(BF10="USD",BF10="CAD",BF10="GBP",BF10="AUD",BF10="EUR"),0,1))) -> 0 | CH10: =IF(B10="",0,(IF(OR(BG10="United States",BG10="Canada",BG10="United Kingdom",BG10="Australia",BG10="Netherlands Antilles",BG10="Bermuda",BG10="Cayman Islands",BG10="British Virgin Islands",BG10="Channel Islands",BG10="Isle of Man",BG10="Australia",BG10="Netherlands",BG10="Germany",BG10="Sweden",BG10="Switzerland",BG10="Austria",BG10="Belgium",BG10="Denmark",BG10="Finland",BG10="Iceland",BG10="Ireland",BG10="Lichtenstein",BG10="Luxemborg",BG10="Norway"),0,1))) -> 0 | CI10: =IF(BO10="Yes",1,0) -> 0 | CJ10: =IF(BP10="Yes",1,0) -> 0 | CK10: =IF(BQ10="Yes",1,0) -> 0 | CL10: =IF(BR10="Yes",1,0) -> 0 | CM10: =IF(BS10="Yes",1,0) -> 0 | CN10: =IF(BT10="Yes",1,0) -> 0 | CO10: =IF(OR(AND(BJ10="Yes",N10="No"),AND(BJ10="Yes",N10="Yes",P10>=6)),1,0) -> 0 | CP10: =IF(BU10="Yes",1,0) -> 0 | CQ10: =IF(AND(BV10="Yes",BW10="No"),1,0) -> 0 | CR10: =IF(BX10="Yes",1,0) -> 0 | CS10: =IF(AP10="",0,IF(AP10>7,1,0)) -> 0 | CT10: =IF(OR(BD10<>"Monthly",BD10<>"Quarterly",BD10<>"Semi-Annually"),0,1) -> 0 | CU10: =IF(BY10="Yes",1,0) -> 0 | CV10: =IF(BZ10="Yes",1,0) -> 0 | CW10: =IF(CA10="Yes",1,0) -> 0 | CX10: =IF(CB10="No",1,0) -> 0 | CY10: =IF(B10="",0,IF(AK10>=5000000,0,1)) -> 0 | CZ10: =IF(B10="",0,IF(AL10>=5000000,0,1)) -> 0 | DA10: =IF(OR(DB10=1,DC10=1,DD10=1),0,IF(B10="",0,IF(OR(AND(AN10="Tier 1",X10="No",OR(AI10>$AJ$3,AJ10>$AJ$4)),(AND(AN10="Tier 1",X10="Yes",AJ10>$AJ$5)),(AND(AN10="Tier 2",X10="No",OR(AI10>$AK$3,AJ10>$AK$4))),(AND(AN10="Tier 2",X10="Yes",AJ10>$AK$5)),(AND(AN10="Tier 3",X10="No",OR(AI10>$AL$3,AJ10>$AL$4))),(AND(AN10="Tier 3",X10="Yes",AJ10>$AL$5))),1,0))) -> 0 | DB10: =IF(OR(DC10=1,DD10=1),0,IF(B10="",0,IF(OR(AND(AN10="Tier 1",X10="No",OR(AI10>$AM$3,AJ10>$AM$4)),(AND(AN10="Tier 1",X10="Yes",AJ10>$AM$5)),(AND(AN10="Tier 2",X10="No",OR(AI10>$AN$3,AJ10>$AN$4))),(AND(AN10="Tier 2",X10="Yes",AJ10>$AN$5)),(AND(AN10="Tier 3",X10="No",OR(AI10>$AO$3,AJ10>$AO$4))),(AND(AN10="Tier 3",X10="Yes",AJ10>$AO$5))),1,0))) -> 0 | DC10: =IF(DD10=1,0,IF(B10="",0,IF(OR(AND(AN10="Tier 1",X10="No",OR(AI10>$AP$3,AJ10>$AP$4)),(AND(AN10="Tier 1",X10="Yes",AJ10>$AP$5)),(AND(AN10="Tier 2",X10="No",OR(AI10>$AQ$3,AJ10>$AQ$4))),(AND(AN10="Tier 2",X10="Yes",AJ10>$AQ$5)),(AND(AN10="Tier 3",X10="No",OR(AI10>$AR$3,AJ10>$AR$4))),(AND(AN10="Tier 3",X10="Yes",AJ10>$AR$5))),1,0))) -> 0 | DD10: =IF(B10="",0,IF(OR(AND(AN10="Tier 1",X10="No",OR(AI10>$AS$3,AJ10>$AS$4)),(AND(AN10="Tier 1",X10="Yes",AJ10>$AS$5)),(AND(AN10="Tier 2",X10="No",OR(AI10>$AT$3,AJ10>$AT$4))),(AND(AN10="Tier 2",X10="Yes",AJ10>$AT$5)),(AND(AN10="Tier 3",X10="No",OR(AI10>$AU$3,AJ10>$AU$4))),(AND(AN10="Tier 3",X10="Yes",AJ10>$AU$5))),1,0)) -> 0 | DE10: =IF((SUM(CF10:CY10)=0),0,W10) -> 0 | DF10: =IF(OR(B10="",DE10>0),0,W10) -> 25589358 | DG10: =IF(B10="",0,IF(COUNTIF(CF10:CY10,1)>0,0,L10-M10)) -> 0 | DH10: =DF10+IF(DE10>0,0,DG10) -> 25589358 | DI10: =IF(B10="","",M10+DG10) -> 25589358 | DJ10: =IF(B10="",0,J10-K10) -> 0 | DK10: =IF(OR(BF10="EUR",BF10="CAD",BF10="GBP",BF10="AUD"),(GB10*(1-V10))+(HH10)+IF(HY10="",0,HY10*(1-U10)),0) -> 0 | DL10: =IF(BF10="EUR",33%,IF(BF10="CAD",38%,IF(BF10="GBP",51%,IF(BF10="AUD",61%,0)))) -> 0 | DM10: =DK10*DL10 -> 0 | DO10: =IF(OR(Y10="Second Lien",Y10="Tier 1 Split Lien",Y10="Tier 2 Split Lien"),DH10,0) -> 0 | DP10: =DO10*DO$6 -> 0 | DQ10: =DH10-DP10 -> 25589358 | DR10: =IF(Y10="Second Lien",DQ10,0) -> 0 | DS10: =DR10*DR$6 -> 0 | DT10: =DQ10-DS10 -> 25589358 | DU10: =IF(BH10="Yes",DT10,0) -> 0 | DV10: =DU10*DU$6 -> 0 | DW10: =DT10-DV10 -> 25589358 | DX10: =IF(OR(BG10="Canada",BG10="United Kingdom",BG10="Australia",BG10="Netherlands Antilles",BG10="Bermuda",BG10="Cayman Islands",BG10="British Virgin Islands",BG10="Channel Islands",BG10="Isle of Man",BG10="Australia",BG10="Netherlands",BG10="Germany",BG10="Sweden",BG10="Switzerland",BG10="Austria",BG10="Belgium",BG10="Denmark",BG10="Finland",BG10="Iceland",BG10="Ireland",BG10="Lichtenstein",BG10="Luxemborg",BG10="Norway"),DW10,0) -> 0 | DY10: =DX10*DX$6 -> 0 | DZ10: =DW10-DY10 -> 25589358 | EA10: =IF(BI10="Yes",DZ10,0) -> 0 | EB10: =EA10*EA$6 -> 0 | EC10: =DZ10-EB10 -> 25589358 | ED10: =IF(OR(Z10="Delayed Draw",Z10="Revolver"),EC10,0) -> 0 | EE10: =ED10*ED$6 -> 0 | EF10: =EC10-EE10 -> 25589358 | EG10: =IF(S10="Yes",EF10,0) -> 0 | EH10: =EG10*EG$6 -> 0 | EI10: =EF10-EH10 -> 25589358 | EJ10: =IF(Q10="Yes",EI10,0) -> 0 | EK10: =EJ10*EJ$6 -> 0 | EL10: =EI10-EK10 -> 25589358 | EM10: =IF(BD10="Semi-Annually",EL10,0) -> 0 | EN10: =EM10*EM$6 -> 0 | EO10: =EL10-EN10 -> 25589358 | EP10: =IF(BK10="Yes",EO10,0) -> 0 | EQ10: =EP10*EP$6 -> 0 | ER10: =EO10-EQ10 -> 25589358 | ES10: =IF(BL10="Yes",ER10,0) -> 0 | ET10: =ES10*ES$6 -> 0 | EU10: =ER10-ET10 -> 25589358 | EV10: =IF(AND(BM10="Yes",OR(BN10="No",AND(BN10="Yes",Inputs!$J$8=Inputs!$J$17+75))),EU10,0) -> 0 | EW10: =EV10*EV$6 -> 0 | EX10: =EU10-EW10 -> 25589358 | EY10: =IF(BW10="Yes",EX10,0) -> 0 | EZ10: =EY10*EY$6 -> 0 | FA10: =EX10-EZ10 -> 25589358 | FB10: =IF(AR10="Yes",FA10,0) -> 0 | FC10: =FB10*FB$6 -> 0 | FD10: =FA10-FC10 -> 25589358 | FE10: =IF(OR(BF10="EUR",BF10="AUD",BF10="CAD",BF10="GBP"),FD10,0) -> 0 | FF10: =FE10*FE$6 -> 0 | FG10: =FD10-FF10 -> 25589358 | FH10: =FG10 -> 25589358 | FI10: =IF(FG10=0,0,VLOOKUP(C10,$GV$10:$GW$406,2,FALSE)*FG10) -> 0 | FJ10: =FG10-FI10 -> 25589358 | FK10: =FJ10 -> 25589358 | FL10: =IF(OR(IC10="",FJ10<0.01),,VLOOKUP(IC10,$GM$10:$GN$406,2,FALSE)*FJ10) -> 0 | FM10: =FJ10-FL10 -> 25589358 | FN10: =FM10 -> 25589358 | FO10: =IF(FM10=0,0,VLOOKUP(C10,$HE$10:$HF$406,2,FALSE)*FM10) -> 0 | FP10: =FM10-FO10 -> 25589358 | FQ10: =IF(SUM(CZ10:DD10)>0,0,IF(AND(AL10>=5000000,AL10<7500000),FP10,0)) -> 0 | FR10: =IF(B10="",0,FQ10*FQ$6*(1-$U10)) -> 0 | FS10: =FP10-FR10 -> 25589358 | FT10: =IF(SUM(CZ10:DD10)>0,0,IF(AL10<15000000,FS10,0)) -> 0 | FU10: =IF(B10="",0,FT10*FT$6*(1-$U10)) -> 0 | FV10: =FS10-FU10 -> 25589358 | FW10: =IF(SUM(CZ10:DD10)>0,0,IF(OR(AND(X10="No",AN10="Tier 1",AI10>$AG$3),AND(X10="No",AN10="Tier 2",AI10>$AH$3),AND(X10="No",AN10="Tier 3",AI10>$AI$3)),FV10,0)) -> 0 | FX10: =IF(SUM(CZ10:DD10)>0,0,IF(OR(AND(X10="No",AN10="Tier 1",AJ10>$AG$4),AND(X10="No",AN10="Tier 2",AJ10>$AH$4),AND(X10="No",AN10="Tier 3",AJ10>$AI$4)),FV10,0)) -> 0 | FY10: =IF(SUM(CZ10:DD10)>0,0,IF(OR(AND(X10="Yes",AN10="Tier 1",AJ10>$AG$5),AND(X10="Yes",AN10="Tier 2",AJ10>$AH$5),AND(X10="Yes",AN10="Tier 3",AJ10>$AI$5)),FV10,0)) -> 0 | FZ10: =IF(SUM(FW10:FY10)>0,FV10,0) -> 0 | GA10: =IF(B10="",0,FZ10*FW$6*(1-MIN(90%,T10))) -> 0 | GB10: =FV10-GA10 -> 25589358 | GC10: =IF(AND(N10="No",DJ10=0),GB10,IF(AND(N10="No",DJ10<>0,K10=0),0,IF(AND(N10="No",DJ10<>0,K10>0,J10<>K10),MAX(0,M10-(DI10-GB10)),DH10))) -> 25589358 | GD10: =+GC10*V10 -> 17281279 | GE10: =IFERROR(GD10/K10,"") -> 0.67533071 | GF10: =IF(IC10="","",IC10) -> 41 | GG10: {=IF(SUM(IF(IC$9:IC9=IC10,1,0))>0,0,SUMIF($IC$10:$IC$406,IC10,$FJ$10:$FJ$406))} -> 1.2675e+08 | GH10: =GG10 -> 1.2675e+08 | GI10: 1 | GJ10: =LARGE($GH$10:$GH$406,GI10) -> 1.2675e+08 | GK10: =IF(GI10>GI$6,0,IF(GI10=$GI$2,$GK$2,IF(GI10<4,$GK$3,$GK$4))) -> 2.5482142e+08 | GL10: =MAX(0,GJ10-GK10) -> 0 | GM10: {=IF(GJ10=0,0,LARGE(IF($GG$10:$GG$406=GJ10,$GF$10:$GF$406,0),COUNTIF($GJ$10:$GJ$406,GJ10)-COUNTIF(GJ$9:GJ9,GJ10)))} -> 41 | GN10: =IF(GJ10=0,0,GL10/GJ10) -> 0 | GP10: 1 | GQ10: =IF(COUNTIF($A$10:A10,A10)<=1,SUMIF($A$10:$A$406,A10,$FH$10:$FH$406),0) -> 26818060 | GR10: 1 | GS10: =LARGE($GQ$10:$GQ$406,GR10) -> 50000000 | GT10: =IF(GR10>GR$6,0,IF(GR10<=GR$2,GT$2,IF(AND(GR10<=$GR$3,GR10>$GR$2),GT$3,GT$4))) -> 67952372 | GU10: =MAX(0,GS10-GT10) -> 0 | GV10: {=IF(GS10=0,0,LARGE(IF($GQ$10:$GQ$406=GS10,$GP$10:$GP$406,0),COUNTIF($GS$10:$GS$406,GS10)-COUNTIF(GS$9:GS9,GS10)))} -> 78 | GW10: =IF(GS10=0,0,GU10/GS10) -> 0 | GY10: 1 | GZ10: =IF(COUNTIF($A$10:A10,A10)<=1,SUMIF($A$10:$A$406,A10,$FH$10:$FH$406),0) -> 26818060 | HA10: 1 | HB10: =LARGE($GZ$10:$GZ$406,HA10) -> 50000000 | HC10: - | HD10: =IF(HA10<6,MAX(0,$HD$2/5),0) -> 0 | HE10: {=IF(HB10=0,0,LARGE(IF($GZ$10:$GZ$406=HB10,$GY$10:$GY$406,0),COUNTIF($HB$10:$HB$406,HB10)-COUNTIF(HB$9:HB9,HB10)))} -> 78 | HF10: =IF(HB10=0,0,HD10/HB10) -> 0 | HH10: =DH10-GB10 -> 0 | HI10: 0 | HJ10: =MIN(HI10,DF10) -> 0 | HL10: 1 | HM10: =SUMIF($C$10:$C$406,HL10,$DH$10:$DH$406) -> 25589358 | HO10: =MIN(HP10:HT10) -> 25589358 | HP10: =IF(B10="","",$M10) -> 25589358 | HQ10: =IF($N10="Yes",IF(P10>=6,0,MIN($T10*$M10,$U10*$M10)),"") | HR10: =IF(AND(N10="Yes",P10>=6),"",IF($S10="Yes",$R10*$M10,"")) | HS10: =IF($Q10="Yes",MIN($M10,$T10*$M10),"") | HT10: =IF(AND($N10="Yes",$P10>=6),"",IF(OR(CZ10=1,DD10=1,),MIN($T10*$M10,$U10*$M10),IF(OR(DA10=1,DB10=1,DC10=1),IF(AK10>=5000000,MIN($T10*$M10,$IF10*$M10),MIN($T10*$M10,$U10*$M10)),""))) | HU10: =IF(DE10>0,DE10,"") | HV10: =IF(B10="",0,$L10-$M10) -> 0 | HW10: =IF(OR(SUM(HQ10:HU10)>0,P10>=6),"",IF($B10="","",1)) -> 1 | HX10: =IF(AND($HU10<>0,OR(HU10<=MIN(HQ10:HT10),SUM(HQ10:HT10)=0)),$HU10,0) | HY10: =IF(AND($HT10<>0,OR(AND($HT10<>$HU10,$HT10<>$HS10,$HT10<>$HR10,$HT10<>$HQ10,$HT10<MIN($HQ10:$HS10),$HT10<HU10),SUM($HQ10:$HS10)+SUM(HU10)=0),IB10<=0),$HT10,0) -> 0 | HZ10: =IF(AND($HS10<>0,OR(AND($HS10<>$HU10,$HS10<>$HT10,$HS10<>$HR10,$HS10<>$HQ10),$HS10<MIN($HQ10:$HR10),$HS10<MIN($HT10:$HU10),SUM($HQ10:$HR10)+SUM($HT10:$HU10)=0)),$HS10,0) | IA10: =IF(AND($HR10<>0,OR(AND($HR10<>$HU10,HR10<>HT10,HR10<>HS10,HR10<>HQ10,HR10<MIN(HS10:HU10)),SUM(HQ10)+SUM(HS10:HU10)=0)),$HR10,0) | IB10: =IF(AND($HQ10<>0,OR(HQ10<=MIN(HR10:HU10),SUM(HR10:HU10)=0)),$HQ10,0) | IC10: =IF(C10="","",INDEX(Lookups!$E$2:$E$69,MATCH('Loan List'!BE10,Lookups!$F$2:$F$69,0))) -> 41 | ID10: =HV10=DG10 -> TRUE | IF10: =IF(B10="","",IF(AND(Y10="Second Lien",OR(DA10=1,DB10=1,DC10=1)),50%,IF(DA10=1,90%,IF(DB10=1,80%,IF(DC10=1,65%,"No Initial Haircut"))))) -> No Initial Haircut
A11: Arcfield Acquisition Corp. | B11: =IF(D11="","",B10+1) -> 2 | C11: =IF(COUNTIF($A$10:A10,A11)>0,C10,C10+1) -> 2 | D11: Arcfield Acquisition Corp. | E11: Arcfield (Term Loan) | G11: 6009486.5 | H11: 6009486.5 | I11: =IF(B11="","",VLOOKUP(BF11,Inputs!$A$12:$J$15,10,FALSE)) -> 1 | J11: =IF(B11="","",G11*I11) -> 6009486.5 | K11: =IF(B11="","",H11*I11) -> 6009486.5 | L11: =IF(B11="","",IF(COUNTIF($CF11:$CY11,1)>0,0,J11)) -> 6009486.5 | M11: =IF(B11="","",IF(COUNTIF($CF11:$CY11,1)>0,0,K11)) -> 6009486.5 | N11: No | O11: N/A | P11: =IF(B11="","",IF(OR(O11="N/A",O11=""),0,YEARFRAC('Borrowing Base'!$J$4,'Loan List'!O11)*12)) -> 0 | Q11: No | R11: 0.9975 | S11: =IF(B11="","",IF(R11<95%,"Yes","No")) -> No | T11: 0.995 | U11: =IF(B11="","",IF(OR(Y11="First Lien",Y11="Split First Lien",Y11="Tier 1 Split Lien",Y11="Tier 2 Split Lien"),50%,30%)) -> 0.5 | V11: =IF(B11="",0,IF(AND(Y11="First Lien",AN11="Tier 1"),IF(AND(X11="Yes",MIN(AH11,$AJ$5)>4.5),(((4.5/MIN(AH11,$AJ$5))*72.5%)+(((MIN(AH11,$AJ$5)-4.5)/MIN(AH11,$AJ$5))*35%)),72.5%),IF(AND(Y11="First Lien",AN11="Tier 2"),IF(AND(X11="Yes",MIN(AH11,$AK$5)>4.5),(((4.5/MIN(AH11,$AK$5))*72.5%)+(((MIN(AH11,$AK$5)-4.5)/MIN(AH11,$AK$5))*35%)),72.5%),IF(AND(X11="Yes",MIN(AH11,$AL$5)>4),(((4/MIN(AH11,$AL$5))*72.5%)+(((MIN(AH11,$AL$5)-4)/MIN(AH11,$AL$5))*35%)),IF(OR(Y11="First Lien",Y11="Split First Lien"),72.5%,IF(Y11="Split Lien", 53%,35%)))))) -> 0.725 | W11: =IF($C11="","",MIN($HP11:$HT11)) -> 6009486.5 | X11: Yes | Y11: First Lien | Z11: Term | AA11: NR | AB11: NR | AC11: 2.68 | AD11: 1.2512861 | AE11: 1.8366382 | AF11: 0.42754938 | AG11: 3.76 | AH11: 3.76 | AI11: 4.3704657 | AJ11: 4.3704657 | AK11: 35900000 | AL11: 61779000 | AM11: 45747 | AN11: =IF(C11="","",(IF(AK11>=50000000,"Tier 1",(IF(OR(AK11>=20000000,AND(AK11>5000000,AC11>=1.25,AF11<=0.65)),"Tier 2","Tier 3"))))) -> Tier 2 | AO11: 48149 | AP11: =IF(C11="","",DAYS360(Inputs!$J$8,AO11)/360) -> 6.1777778 | AQ11: =IF(C11="","",AP11) -> 6.1777778 | AR11: No | AS11: 0 | AT11: Yes | AU11: 0.01 | AV11: 0.05 | AW11: 0.043079 | AX11: =IF(C11="","",MAX(AU11,AW11)) -> 0.043079 | AY11: 0 | AZ11: 0 | BA11: 0 | BB11: =IF(B11="","",IF(AR11="No",AV11-AZ11,"")) -> 0.05 | BC11: =IF(B11="","",IF(AR11="Yes",AS11-BA11,"")) | BD11: Quarterly | BE11: Aerospace & Defense | BF11: USD | BG11: United States | BH11: No | BI11: =IF(B11="","",IF(OR(AND(AZ11>0,BB11>=2.5%,BB11<4%),AND(BA11>0,BC11>=6%,BC11<8%)),"Yes","No")) -> No | BJ11: =IF(B11="","",IF(OR(AND(AZ11>0,BB11<2.5%),AND(BA11>0,BC11<6%)),"Yes","No")) -> No | BK11: No | BL11: No | BM11: No | BN11: No | BO11: No | BP11: No | BQ11: No | BR11: No | BS11: No | BT11: No | BU11: No | BV11: No | BW11: No | BX11: No | BY11: No | BZ11: No | CA11: No | CB11: Yes | CC11: =IF(B11="","",IF(AT11="No",((BB11+AW11)-$AZ$4),((BB11+AX11)-$AZ$4))*IF(DE11>0,0,M11)) -> 299612.56 | CD11: =IF(B11="","",AY11*(L11-M11)*IF(DE11>0,0,1)) -> 0 | CF11: =IF(AND(B11<>"",R11<=85%),1,0) -> 0 | CG11: =IF(B11="",0,(IF(OR(BF11="USD",BF11="CAD",BF11="GBP",BF11="AUD",BF11="EUR"),0,1))) -> 0 | CH11: =IF(B11="",0,(IF(OR(BG11="United States",BG11="Canada",BG11="United Kingdom",BG11="Australia",BG11="Netherlands Antilles",BG11="Bermuda",BG11="Cayman Islands",BG11="British Virgin Islands",BG11="Channel Islands",BG11="Isle of Man",BG11="Australia",BG11="Netherlands",BG11="Germany",BG11="Sweden",BG11="Switzerland",BG11="Austria",BG11="Belgium",BG11="Denmark",BG11="Finland",BG11="Iceland",BG11="Ireland",BG11="Lichtenstein",BG11="Luxemborg",BG11="Norway"),0,1))) -> 0 | CI11: =IF(BO11="Yes",1,0) -> 0 | CJ11: =IF(BP11="Yes",1,0) -> 0 | CK11: =IF(BQ11="Yes",1,0) -> 0 | CL11: =IF(BR11="Yes",1,0) -> 0 | CM11: =IF(BS11="Yes",1,0) -> 0 | CN11: =IF(BT11="Yes",1,0) -> 0 | CO11: =IF(OR(AND(BJ11="Yes",N11="No"),AND(BJ11="Yes",N11="Yes",P11>=6)),1,0) -> 0 | CP11: =IF(BU11="Yes",1,0) -> 0 | CQ11: =IF(AND(BV11="Yes",BW11="No"),1,0) -> 0 | CR11: =IF(BX11="Yes",1,0) -> 0 | CS11: =IF(AP11="",0,IF(AP11>7,1,0)) -> 0 | CT11: =IF(OR(BD11<>"Monthly",BD11<>"Quarterly",BD11<>"Semi-Annually"),0,1) -> 0 | CU11: =IF(BY11="Yes",1,0) -> 0 | CV11: =IF(BZ11="Yes",1,0) -> 0 | CW11: =IF(CA11="Yes",1,0) -> 0 | CX11: =IF(CB11="No",1,0) -> 0 | CY11: =IF(B11="",0,IF(AK11>=5000000,0,1)) -> 0 | CZ11: =IF(B11="",0,IF(AL11>=5000000,0,1)) -> 0 | DA11: =IF(OR(DB11=1,DC11=1,DD11=1),0,IF(B11="",0,IF(OR(AND(AN11="Tier 1",X11="No",OR(AI11>$AJ$3,AJ11>$AJ$4)),(AND(AN11="Tier 1",X11="Yes",AJ11>$AJ$5)),(AND(AN11="Tier 2",X11="No",OR(AI11>$AK$3,AJ11>$AK$4))),(AND(AN11="Tier 2",X11="Yes",AJ11>$AK$5)),(AND(AN11="Tier 3",X11="No",OR(AI11>$AL$3,AJ11>$AL$4))),(AND(AN11="Tier 3",X11="Yes",AJ11>$AL$5))),1,0))) -> 0 | DB11: =IF(OR(DC11=1,DD11=1),0,IF(B11="",0,IF(OR(AND(AN11="Tier 1",X11="No",OR(AI11>$AM$3,AJ11>$AM$4)),(AND(AN11="Tier 1",X11="Yes",AJ11>$AM$5)),(AND(AN11="Tier 2",X11="No",OR(AI11>$AN$3,AJ11>$AN$4))),(AND(AN11="Tier 2",X11="Yes",AJ11>$AN$5)),(AND(AN11="Tier 3",X11="No",OR(AI11>$AO$3,AJ11>$AO$4))),(AND(AN11="Tier 3",X11="Yes",AJ11>$AO$5))),1,0))) -> 0 | DC11: =IF(DD11=1,0,IF(B11="",0,IF(OR(AND(AN11="Tier 1",X11="No",OR(AI11>$AP$3,AJ11>$AP$4)),(AND(AN11="Tier 1",X11="Yes",AJ11>$AP$5)),(AND(AN11="Tier 2",X11="No",OR(AI11>$AQ$3,AJ11>$AQ$4))),(AND(AN11="Tier 2",X11="Yes",AJ11>$AQ$5)),(AND(AN11="Tier 3",X11="No",OR(AI11>$AR$3,AJ11>$AR$4))),(AND(AN11="Tier 3",X11="Yes",AJ11>$AR$5))),1,0))) -> 0 | DD11: =IF(B11="",0,IF(OR(AND(AN11="Tier 1",X11="No",OR(AI11>$AS$3,AJ11>$AS$4)),(AND(AN11="Tier 1",X11="Yes",AJ11>$AS$5)),(AND(AN11="Tier 2",X11="No",OR(AI11>$AT$3,AJ11>$AT$4))),(AND(AN11="Tier 2",X11="Yes",AJ11>$AT$5)),(AND(AN11="Tier 3",X11="No",OR(AI11>$AU$3,AJ11>$AU$4))),(AND(AN11="Tier 3",X11="Yes",AJ11>$AU$5))),1,0)) -> 0 | DE11: =IF((SUM(CF11:CY11)=0),0,W11) -> 0 | DF11: =IF(OR(B11="",DE11>0),0,W11) -> 6009486.5 | DG11: =IF(B11="",0,IF(COUNTIF(CF11:CY11,1)>0,0,L11-M11)) -> 0 | DH11: =DF11+IF(DE11>0,0,DG11) -> 6009486.5 | DI11: =IF(B11="","",M11+DG11) -> 6009486.5 | DJ11: =IF(B11="",0,J11-K11) -> 0 | DK11: =IF(OR(BF11="EUR",BF11="CAD",BF11="GBP",BF11="AUD"),(GB11*(1-V11))+(HH11)+IF(HY11="",0,HY11*(1-U11)),0) -> 0 | DL11: =IF(BF11="EUR",33%,IF(BF11="CAD",38%,IF(BF11="GBP",51%,IF(BF11="AUD",61%,0)))) -> 0 | DM11: =DK11*DL11 -> 0 | DO11: =IF(OR(Y11="Second Lien",Y11="Tier 1 Split Lien",Y11="Tier 2 Split Lien"),DH11,0) -> 0 | DP11: =DO11*DO$6 -> 0 | DQ11: =DH11-DP11 -> 6009486.5 | DR11: =IF(Y11="Second Lien",DQ11,0) -> 0 | DS11: =DR11*DR$6 -> 0 | DT11: =DQ11-DS11 -> 6009486.5 | DU11: =IF(BH11="Yes",DT11,0) -> 0 | DV11: =DU11*DU$6 -> 0 | DW11: =DT11-DV11 -> 6009486.5 | DX11: =IF(OR(BG11="Canada",BG11="United Kingdom",BG11="Australia",BG11="Netherlands Antilles",BG11="Bermuda",BG11="Cayman Islands",BG11="British Virgin Islands",BG11="Channel Islands",BG11="Isle of Man",BG11="Australia",BG11="Netherlands",BG11="Germany",BG11="Sweden",BG11="Switzerland",BG11="Austria",BG11="Belgium",BG11="Denmark",BG11="Finland",BG11="Iceland",BG11="Ireland",BG11="Lichtenstein",BG11="Luxemborg",BG11="Norway"),DW11,0) -> 0 | DY11: =DX11*DX$6 -> 0 | DZ11: =DW11-DY11 -> 6009486.5 | EA11: =IF(BI11="Yes",DZ11,0) -> 0 | EB11: =EA11*EA$6 -> 0 | EC11: =DZ11-EB11 -> 6009486.5 | ED11: =IF(OR(Z11="Delayed Draw",Z11="Revolver"),EC11,0) -> 0 | EE11: =ED11*ED$6 -> 0 | EF11: =EC11-EE11 -> 6009486.5 | EG11: =IF(S11="Yes",EF11,0) -> 0 | EH11: =EG11*EG$6 -> 0 | EI11: =EF11-EH11 -> 6009486.5 | EJ11: =IF(Q11="Yes",EI11,0) -> 0 | EK11: =EJ11*EJ$6 -> 0 | EL11: =EI11-EK11 -> 6009486.5 | EM11: =IF(BD11="Semi-Annually",EL11,0) -> 0 | EN11: =EM11*EM$6 -> 0 | EO11: =EL11-EN11 -> 6009486.5 | EP11: =IF(BK11="Yes",EO11,0) -> 0 | EQ11: =EP11*EP$6 -> 0 | ER11: =EO11-EQ11 -> 6009486.5 | ES11: =IF(BL11="Yes",ER11,0) -> 0 | ET11: =ES11*ES$6 -> 0 | EU11: =ER11-ET11 -> 6009486.5 | EV11: =IF(AND(BM11="Yes",OR(BN11="No",AND(BN11="Yes",Inputs!$J$8=Inputs!$J$17+75))),EU11,0) -> 0 | EW11: =EV11*EV$6 -> 0 | EX11: =EU11-EW11 -> 6009486.5 | EY11: =IF(BW11="Yes",EX11,0) -> 0 | EZ11: =EY11*EY$6 -> 0 | FA11: =EX11-EZ11 -> 6009486.5 | FB11: =IF(AR11="Yes",FA11,0) -> 0 | FC11: =FB11*FB$6 -> 0 | FD11: =FA11-FC11 -> 6009486.5 | FE11: =IF(OR(BF11="EUR",BF11="AUD",BF11="CAD",BF11="GBP"),FD11,0) -> 0 | FF11: =FE11*FE$6 -> 0 | FG11: =FD11-FF11 -> 6009486.5 | FH11: =FG11 -> 6009486.5 | FI11: =IF(FG11=0,0,VLOOKUP(C11,$GV$10:$GW$406,2,FALSE)*FG11) -> 0 | FJ11: =FG11-FI11 -> 6009486.5 | FK11: =FJ11 -> 6009486.5 | FL11: =IF(OR(IC11="",FJ11<0.01),,VLOOKUP(IC11,$GM$10:$GN$406,2,FALSE)*FJ11) -> 0 | FM11: =FJ11-FL11 -> 6009486.5 | FN11: =FM11 -> 6009486.5 | FO11: =IF(FM11=0,0,VLOOKUP(C11,$HE$10:$HF$406,2,FALSE)*FM11) -> 0 | FP11: =FM11-FO11 -> 6009486.5 | FQ11: =IF(SUM(CZ11:DD11)>0,0,IF(AND(AL11>=5000000,AL11<7500000),FP11,0)) -> 0 | FR11: =IF(B11="",0,FQ11*FQ$6*(1-$U11)) -> 0 | FS11: =FP11-FR11 -> 6009486.5 | FT11: =IF(SUM(CZ11:DD11)>0,0,IF(AL11<15000000,FS11,0)) -> 0 | FU11: =IF(B11="",0,FT11*FT$6*(1-$U11)) -> 0 | FV11: =FS11-FU11 -> 6009486.5 | FW11: =IF(SUM(CZ11:DD11)>0,0,IF(OR(AND(X11="No",AN11="Tier 1",AI11>$AG$3),AND(X11="No",AN11="Tier 2",AI11>$AH$3),AND(X11="No",AN11="Tier 3",AI11>$AI$3)),FV11,0)) -> 0 | FX11: =IF(SUM(CZ11:DD11)>0,0,IF(OR(AND(X11="No",AN11="Tier 1",AJ11>$AG$4),AND(X11="No",AN11="Tier 2",AJ11>$AH$4),AND(X11="No",AN11="Tier 3",AJ11>$AI$4)),FV11,0)) -> 0 | FY11: =IF(SUM(CZ11:DD11)>0,0,IF(OR(AND(X11="Yes",AN11="Tier 1",AJ11>$AG$5),AND(X11="Yes",AN11="Tier 2",AJ11>$AH$5),AND(X11="Yes",AN11="Tier 3",AJ11>$AI$5)),FV11,0)) -> 0 | FZ11: =IF(SUM(FW11:FY11)>0,FV11,0) -> 0 | GA11: =IF(B11="",0,FZ11*FW$6*(1-MIN(90%,T11))) -> 0 | GB11: =FV11-GA11 -> 6009486.5 | GC11: =IF(AND(N11="No",DJ11=0),GB11,IF(AND(N11="No",DJ11<>0,K11=0),0,IF(AND(N11="No",DJ11<>0,K11>0,J11<>K11),MAX(0,M11-(DI11-GB11)),DH11))) -> 6009486.5 | GD11: =+GC11*V11 -> 4356877.7 | GE11: =IFERROR(GD11/K11,"") -> 0.725 | GF11: =IF(IC11="","",IC11) -> 1 | GG11: {=IF(SUM(IF(IC$9:IC10=IC11,1,0))>0,0,SUMIF($IC$10:$IC$406,IC11,$FJ$10:$FJ$406))} -> 57413376 | GH11: =GG11 -> 57413376 | GI11: =GI10+1 -> 2 | GJ11: =LARGE($GH$10:$GH$406,GI11) -> 1.0592467e+08 | GK11: =IF(GI11>GI$6,0,IF(GI11=$GI$2,$GK$2,IF(GI11<4,$GK$3,$GK$4))) -> 1.5289285e+08 | GL11: =MAX(0,GJ11-GK11) -> 0 | GM11: {=IF(GJ11=0,0,LARGE(IF($GG$10:$GG$406=GJ11,$GF$10:$GF$406,0),COUNTIF($GJ$10:$GJ$406,GJ11)-COUNTIF(GJ$9:GJ10,GJ11)))} -> 46 | GN11: =IF(GJ11=0,0,GL11/GJ11) -> 0 | GP11: =IF(C11="","",IF(ISERROR(MATCH(C11,C10:C$10,0)),MAX(GP10:GP$10)+1,INDEX(GP10:GP$10,MATCH(C11,C10:C$10,0)))) -> 2 | GQ11: =IF(COUNTIF($A$10:A11,A11)<=1,SUMIF($A$10:$A$406,A11,$FH$10:$FH$406),0) -> 6009486.5 | GR11: =GR10+1 -> 2 | GS11: =LARGE($GQ$10:$GQ$406,GR11) -> 41568911 | GT11: =IF(GR11>GR$6,0,IF(GR11<=GR$2,GT$2,IF(AND(GR11<=$GR$3,GR11>$GR$2),GT$3,GT$4))) -> 67952372 | GU11: =MAX(0,GS11-GT11) -> 0 | GV11: {=IF(GS11=0,0,LARGE(IF($GQ$10:$GQ$406=GS11,$GP$10:$GP$406,0),COUNTIF($GS$10:$GS$406,GS11)-COUNTIF(GS$9:GS10,GS11)))} -> 11 | GW11: =IF(GS11=0,0,GU11/GS11) -> 0 | GY11: =IF(C11="","",IF(ISERROR(MATCH(C11,C10:C$10,0)),MAX(GP10:GP$10)+1,INDEX(GP10:GP$10,MATCH(C11,C10:C$10,0)))) -> 2 | GZ11: =IF(COUNTIF($A$10:A11,A11)<=1,SUMIF($A$10:$A$406,A11,$FH$10:$FH$406),0) -> 6009486.5 | HA11: =HA10+1 -> 2 | HB11: =LARGE($GZ$10:$GZ$406,HA11) -> 41568911 | HC11: - | HD11: =IF(HA11<6,MAX(0,$HD$2/5),0) -> 0 | HE11: {=IF(HB11=0,0,LARGE(IF($GZ$10:$GZ$406=HB11,$GY$10:$GY$406,0),COUNTIF($HB$10:$HB$406,HB11)-COUNTIF(HB$9:HB10,HB11)))} -> 11 | HF11: =IF(HB11=0,0,HD11/HB11) -> 0 | HH11: =DH11-GB11 -> 0 | HI11: 0 | HJ11: =MIN(HI11,DF11) -> 0 | HL11: =IF(COUNTIF($C$10:$C$406,HL10+1),HL10+1,"") -> 2 | HM11: =SUMIF($C$10:$C$406,HL11,$DH$10:$DH$406) -> 6009486.5 | HO11: =MIN(HP11:HT11) -> 6009486.5 | HP11: =IF(B11="","",$M11) -> 6009486.5 | HQ11: =IF($N11="Yes",IF(P11>=6,0,MIN($T11*$M11,$U11*$M11)),"") | HR11: =IF(AND(N11="Yes",P11>=6),"",IF($S11="Yes",$R11*$M11,"")) | HS11: =IF($Q11="Yes",MIN($M11,$T11*$M11),"") | HT11: =IF(AND($N11="Yes",$P11>=6),"",IF(OR(CZ11=1,DD11=1,),MIN($T11*$M11,$U11*$M11),IF(OR(DA11=1,DB11=1,DC11=1),IF(AK11>=5000000,MIN($T11*$M11,$IF11*$M11),MIN($T11*$M11,$U11*$M11)),""))) | HU11: =IF(DE11>0,DE11,"") | HV11: =IF(B11="",0,$L11-$M11) -> 0 | HW11: =IF(OR(SUM(HQ11:HU11)>0,P11>=6),"",IF($B11="","",1)) -> 1 | HX11: =IF(AND($HU11<>0,OR(HU11<=MIN(HQ11:HT11),SUM(HQ11:HT11)=0)),$HU11,0) | HY11: =IF(AND($HT11<>0,OR(AND($HT11<>$HU11,$HT11<>$HS11,$HT11<>$HR11,$HT11<>$HQ11,$HT11<MIN($HQ11:$HS11),$HT11<HU11),SUM($HQ11:$HS11)+SUM(HU11)=0),IB11<=0),$HT11,0) -> 0 | HZ11: =IF(AND($HS11<>0,OR(AND($HS11<>$HU11,$HS11<>$HT11,$HS11<>$HR11,$HS11<>$HQ11),$HS11<MIN($HQ11:$HR11),$HS11<MIN($HT11:$HU11),SUM($HQ11:$HR11)+SUM($HT11:$HU11)=0)),$HS11,0) | IA11: =IF(AND($HR11<>0,OR(AND($HR11<>$HU11,HR11<>HT11,HR11<>HS11,HR11<>HQ11,HR11<MIN(HS11:HU11)),SUM(HQ11)+SUM(HS11:HU11)=0)),$HR11,0) | IB11: =IF(AND($HQ11<>0,OR(HQ11<=MIN(HR11:HU11),SUM(HR11:HU11)=0)),$HQ11,0) | IC11: =IF(C11="","",INDEX(Lookups!$E$2:$E$69,MATCH('Loan List'!BE11,Lookups!$F$2:$F$69,0))) -> 1 | ID11: =HV11=DG11 -> TRUE | IF11: =IF(B11="","",IF(AND(Y11="Second Lien",OR(DA11=1,DB11=1,DC11=1)),50%,IF(DA11=1,90%,IF(DB11=1,80%,IF(DC11=1,65%,"No Initial Haircut"))))) -> No Initial Haircut
